<?xml version="1.0"?>
<robot xmlns:xacro="http://www.ros.org/wiki/xacro" name="dummy">
  <xacro:macro name="primeu_robot_links">
  <!-- Link body_base -->
  <link name="body_base">
    <inertial>
      <origin xyz="-2.68307e-05 -5.24724e-06 0.0105121" rpy="0 0 0"/>
      <mass value="1.87"/>
      <inertia ixx="0.0017335" ixy="9.91754e-07" ixz="-1.1515e-06" iyy="0.00173467" iyz="-1.1451e-06" izz="0.00189114"/>
    </inertial>
    <!-- Part body_base -->
    <visual>
      <origin xyz="4.85723e-17 1.11022e-16 -0.0417" rpy="-1.5708 5.55112e-17 5.55112e-17"/>
      <geometry>
        <mesh filename="package://primeu_description/assets/body_base.stl"/>
      </geometry>
      <material name="body_base_material">
        <color rgba="0.615686 0.811765 0.929412 1"/>
      </material>
    </visual>
    <collision>
      <origin xyz="4.85723e-17 1.11022e-16 -0.0417" rpy="-1.5708 5.55112e-17 5.55112e-17"/>
      <geometry>
        <mesh filename="package://primeu_description/assets/body_base.stl"/>
      </geometry>
    </collision>
    <!-- Part erob90hi_xx_18ex_v0001 -->
    <visual>
      <origin xyz="-3.1225e-17 6.59195e-17 0.0363" rpy="-3.14159 -1.5708 0"/>
      <geometry>
        <mesh filename="package://primeu_description/assets/erob90hi_xx_18ex_v0001.stl"/>
      </geometry>
      <material name="erob90hi_xx_18ex_v0001_material">
        <color rgba="0.615686 0.811765 0.929412 1"/>
      </material>
    </visual>
    <collision>
      <origin xyz="-3.1225e-17 6.59195e-17 0.0363" rpy="-3.14159 -1.5708 0"/>
      <geometry>
        <mesh filename="package://primeu_description/assets/erob90hi_xx_18ex_v0001.stl"/>
      </geometry>
    </collision>
  </link>
  <!-- Link waist_yaw_link -->
  <link name="waist_yaw_link">
    <inertial>
      <origin xyz="8.16627e-09 -0.0121206 -0.0157131" rpy="0 0 0"/>
      <mass value="0.271814"/>
      <inertia ixx="0.00029564" ixy="1.09892e-10" ixz="-4.9866e-12" iyy="0.000447173" iyz="-4.42578e-05" izz="0.000611761"/>
    </inertial>
    <!-- Part waist_bear_stopper -->
    <visual>
      <origin xyz="-1.61018e-14 -0.0265 -0.035" rpy="1.5708 4.06897e-14 4.36873e-14"/>
      <geometry>
        <mesh filename="package://primeu_description/assets/waist_bear_stopper.stl"/>
      </geometry>
      <material name="waist_bear_stopper_material">
        <color rgba="0.647059 0.647059 0.647059 1"/>
      </material>
    </visual>
    <collision>
      <origin xyz="-1.61018e-14 -0.0265 -0.035" rpy="1.5708 4.06897e-14 4.36873e-14"/>
      <geometry>
        <mesh filename="package://primeu_description/assets/waist_bear_stopper.stl"/>
      </geometry>
    </collision>
    <!-- Part bearing_10_22_6 -->
    <visual>
      <origin xyz="-1.29592e-14 -0.021 -0.035" rpy="-1.5708 4.08562e-14 4.76841e-14"/>
      <geometry>
        <mesh filename="package://primeu_description/assets/bearing_10_22_6.stl"/>
      </geometry>
      <material name="bearing_10_22_6_material">
        <color rgba="0.231373 0.380392 0.705882 1"/>
      </material>
    </visual>
    <collision>
      <origin xyz="-1.29592e-14 -0.021 -0.035" rpy="-1.5708 4.08562e-14 4.76841e-14"/>
      <geometry>
        <mesh filename="package://primeu_description/assets/bearing_10_22_6.stl"/>
      </geometry>
    </collision>
    <!-- Part waist_bear_stopper_2 -->
    <visual>
      <origin xyz="1.459e-14 0.0265 -0.035" rpy="-1.5708 4.01901e-14 4.95715e-14"/>
      <geometry>
        <mesh filename="package://primeu_description/assets/waist_bear_stopper.stl"/>
      </geometry>
      <material name="waist_bear_stopper_2_material">
        <color rgba="0.647059 0.647059 0.647059 1"/>
      </material>
    </visual>
    <collision>
      <origin xyz="1.459e-14 0.0265 -0.035" rpy="-1.5708 4.01901e-14 4.95715e-14"/>
      <geometry>
        <mesh filename="package://primeu_description/assets/waist_bear_stopper.stl"/>
      </geometry>
    </collision>
    <!-- Part bearing_10_22_6_2 -->
    <visual>
      <origin xyz="1.13728e-14 0.021 -0.035" rpy="-1.5708 4.01901e-14 4.95715e-14"/>
      <geometry>
        <mesh filename="package://primeu_description/assets/bearing_10_22_6.stl"/>
      </geometry>
      <material name="bearing_10_22_6_2_material">
        <color rgba="0.231373 0.380392 0.705882 1"/>
      </material>
    </visual>
    <collision>
      <origin xyz="1.13728e-14 0.021 -0.035" rpy="-1.5708 4.01901e-14 4.95715e-14"/>
      <geometry>
        <mesh filename="package://primeu_description/assets/bearing_10_22_6.stl"/>
      </geometry>
    </collision>
    <!-- Part waist_base -->
    <visual>
      <origin xyz="9.69097e-18 -2.16041e-18 0" rpy="-1.5708 -3.56131e-41 4.93038e-32"/>
      <geometry>
        <mesh filename="package://primeu_description/assets/waist_base.stl"/>
      </geometry>
      <material name="waist_base_material">
        <color rgba="0.647059 0.647059 0.647059 1"/>
      </material>
    </visual>
    <collision>
      <origin xyz="9.69097e-18 -2.16041e-18 0" rpy="-1.5708 -3.56131e-41 4.93038e-32"/>
      <geometry>
        <mesh filename="package://primeu_description/assets/waist_base.stl"/>
      </geometry>
    </collision>
  </link>
  <!-- Link waist_roll_link -->
  <link name="waist_roll_link">
    <inertial>
      <origin xyz="-5.81433e-13 -5.71828e-17 -0.0177" rpy="0 0 0"/>
      <mass value="0.125178"/>
      <inertia ixx="1.24231e-05" ixy="-2.55762e-19" ixz="2.72448e-16" iyy="2.84421e-05" iyz="3.98141e-19" izz="2.01802e-05"/>
    </inertial>
    <!-- Part waist_cross_shaft -->
    <visual>
      <origin xyz="-4.61382e-18 0 -0.0177" rpy="1.41056e-14 -1.57039e-14 -2.83107e-15"/>
      <geometry>
        <mesh filename="package://primeu_description/assets/waist_cross_shaft.stl"/>
      </geometry>
      <material name="waist_cross_shaft_material">
        <color rgba="0.768627 0.886275 0.952941 1"/>
      </material>
    </visual>
    <collision>
      <origin xyz="-4.61382e-18 0 -0.0177" rpy="1.41056e-14 -1.57039e-14 -2.83107e-15"/>
      <geometry>
        <mesh filename="package://primeu_description/assets/waist_cross_shaft.stl"/>
      </geometry>
    </collision>
    <!-- Part shaft_m10 -->
    <visual>
      <origin xyz="-4.61382e-18 0 -0.0177" rpy="1.3148e-14 -1.98673e-14 1.52656e-15"/>
      <geometry>
        <mesh filename="package://primeu_description/assets/shaft_m10.stl"/>
      </geometry>
      <material name="shaft_m10_material">
        <color rgba="0.917647 0.917647 0.917647 1"/>
      </material>
    </visual>
    <collision>
      <origin xyz="-4.61382e-18 0 -0.0177" rpy="1.3148e-14 -1.98673e-14 1.52656e-15"/>
      <geometry>
        <mesh filename="package://primeu_description/assets/shaft_m10.stl"/>
      </geometry>
    </collision>
  </link>
  <!-- Link chest_link__configuration_default -->
  <link name="chest_link__configuration_default">
    <inertial>
      <origin xyz="0.00699413 0.173176 0.0230026" rpy="0 0 0"/>
      <mass value="13.2234"/>
      <inertia ixx="0.170026" ixy="-0.00576574" ixz="3.70304e-05" iyy="0.0798703" iyz="2.482e-05" izz="0.12168"/>
    </inertial>
    <!-- Part neck_base -->
    <visual>
      <origin xyz="0.01443 0.3005 0.023" rpy="-1.5708 1.5708 0"/>
      <geometry>
        <mesh filename="package://primeu_description/assets/neck_base.stl"/>
      </geometry>
      <material name="neck_base_material">
        <color rgba="0.647059 0.647059 0.647059 1"/>
      </material>
    </visual>
    <collision>
      <origin xyz="0.01443 0.3005 0.023" rpy="-1.5708 1.5708 0"/>
      <geometry>
        <mesh filename="package://primeu_description/assets/neck_base.stl"/>
      </geometry>
    </collision>
    <!-- Part shoulder_right_base -->
    <visual>
      <origin xyz="0.0279176 -0.237517 0.0234807" rpy="-1.5708 1.5708 0"/>
      <geometry>
        <mesh filename="package://primeu_description/assets/shoulder_right_base.stl"/>
      </geometry>
      <material name="shoulder_right_base_material">
        <color rgba="0.980392 0.713725 0.00392157 1"/>
      </material>
    </visual>
    <collision>
      <origin xyz="0.0279176 -0.237517 0.0234807" rpy="-1.5708 1.5708 0"/>
      <geometry>
        <mesh filename="package://primeu_description/assets/shoulder_right_base.stl"/>
      </geometry>
    </collision>
    <!-- Part waist_link -->
    <visual>
      <origin xyz="0.05 1.62112e-12 -0.065" rpy="-3.14159 -1.5708 0"/>
      <geometry>
        <mesh filename="package://primeu_description/assets/waist_link.stl"/>
      </geometry>
      <material name="waist_link_material">
        <color rgba="0.498039 0.498039 0.498039 1"/>
      </material>
    </visual>
    <collision>
      <origin xyz="0.05 1.62112e-12 -0.065" rpy="-3.14159 -1.5708 0"/>
      <geometry>
        <mesh filename="package://primeu_description/assets/waist_link.stl"/>
      </geometry>
    </collision>
    <!-- Part 00 -->
    <visual>
      <origin xyz="0.05 0.07 -0.085" rpy="3.14159 1.5708 0"/>
      <geometry>
        <mesh filename="package://primeu_description/assets/00.stl"/>
      </geometry>
      <material name="00_material">
        <color rgba="0.231373 0.380392 0.705882 1"/>
      </material>
    </visual>
    <collision>
      <origin xyz="0.05 0.07 -0.085" rpy="3.14159 1.5708 0"/>
      <geometry>
        <mesh filename="package://primeu_description/assets/00.stl"/>
      </geometry>
    </collision>
    <!-- Part bulkhead -->
    <visual>
      <origin xyz="0.0069 0.196 0.023" rpy="2.22045e-16 1.5708 0"/>
      <geometry>
        <mesh filename="package://primeu_description/assets/bulkhead.stl"/>
      </geometry>
      <material name="bulkhead_material">
        <color rgba="0.917647 0.917647 0.917647 1"/>
      </material>
    </visual>
    <collision>
      <origin xyz="0.0069 0.196 0.023" rpy="2.22045e-16 1.5708 0"/>
      <geometry>
        <mesh filename="package://primeu_description/assets/bulkhead.stl"/>
      </geometry>
    </collision>
    <!-- Part shoulder_motor_base -->
    <visual>
      <origin xyz="0.01443 0.24 0.116" rpy="6.65601e-30 -1.5708 0"/>
      <geometry>
        <mesh filename="package://primeu_description/assets/shoulder_motor_base.stl"/>
      </geometry>
      <material name="shoulder_motor_base_material">
        <color rgba="0.917647 0.917647 0.917647 1"/>
      </material>
    </visual>
    <collision>
      <origin xyz="0.01443 0.24 0.116" rpy="6.65601e-30 -1.5708 0"/>
      <geometry>
        <mesh filename="package://primeu_description/assets/shoulder_motor_base.stl"/>
      </geometry>
    </collision>
    <!-- Part crank -->
    <visual>
      <origin xyz="-8.5893e-12 0.07 -0.0695" rpy="3.14159 1.5708 0"/>
      <geometry>
        <mesh filename="package://primeu_description/assets/crank.stl"/>
      </geometry>
      <material name="crank_material">
        <color rgba="0.615686 0.811765 0.929412 1"/>
      </material>
    </visual>
    <collision>
      <origin xyz="-8.5893e-12 0.07 -0.0695" rpy="3.14159 1.5708 0"/>
      <geometry>
        <mesh filename="package://primeu_description/assets/crank.stl"/>
      </geometry>
    </collision>
    <!-- Part batt -->
    <visual>
      <origin xyz="0.00742536 0.246 -0.033" rpy="-7.87311e-14 -1.3739e-15 1.5708"/>
      <geometry>
        <mesh filename="package://primeu_description/assets/batt.stl"/>
      </geometry>
      <material name="batt_material">
        <color rgba="0.615686 0.811765 0.929412 1"/>
      </material>
    </visual>
    <collision>
      <origin xyz="0.00742536 0.246 -0.033" rpy="-7.87311e-14 -1.3739e-15 1.5708"/>
      <geometry>
        <mesh filename="package://primeu_description/assets/batt.stl"/>
      </geometry>
    </collision>
    <!-- Part computer -->
    <visual>
      <origin xyz="0.00741249 0.1575 0.023" rpy="1.5708 1.80411e-16 1.92778e-29"/>
      <geometry>
        <mesh filename="package://primeu_description/assets/computer.stl"/>
      </geometry>
      <material name="computer_material">
        <color rgba="0.231373 0.380392 0.705882 1"/>
      </material>
    </visual>
    <collision>
      <origin xyz="0.00741249 0.1575 0.023" rpy="1.5708 1.80411e-16 1.92778e-29"/>
      <geometry>
        <mesh filename="package://primeu_description/assets/computer.stl"/>
      </geometry>
    </collision>
    <!-- Part right_thoracic_cavity -->
    <visual>
      <origin xyz="-0.0001 0.07 -0.07" rpy="6.65601e-30 -1.5708 0"/>
      <geometry>
        <mesh filename="package://primeu_description/assets/right_thoracic_cavity.stl"/>
      </geometry>
      <material name="right_thoracic_cavity_material">
        <color rgba="0.498039 0.498039 0.498039 1"/>
      </material>
    </visual>
    <collision>
      <origin xyz="-0.0001 0.07 -0.07" rpy="6.65601e-30 -1.5708 0"/>
      <geometry>
        <mesh filename="package://primeu_description/assets/right_thoracic_cavity.stl"/>
      </geometry>
    </collision>
    <!-- Part body_back -->
    <visual>
      <origin xyz="0.000942413 -0.237517 0.0225193" rpy="-1.5708 -1.5708 0"/>
      <geometry>
        <mesh filename="package://primeu_description/assets/body_back.stl"/>
      </geometry>
      <material name="body_back_material">
        <color rgba="0.768627 0.886275 0.952941 1"/>
      </material>
    </visual>
    <collision>
      <origin xyz="0.000942413 -0.237517 0.0225193" rpy="-1.5708 -1.5708 0"/>
      <geometry>
        <mesh filename="package://primeu_description/assets/body_back.stl"/>
      </geometry>
    </collision>
    <!-- Part 00_2 -->
    <visual>
      <origin xyz="0.05 1.62133e-12 0.1115" rpy="3.14159 1.5708 0"/>
      <geometry>
        <mesh filename="package://primeu_description/assets/00__2.stl"/>
      </geometry>
      <material name="00_2_material">
        <color rgba="0.917647 0.917647 0.917647 1"/>
      </material>
    </visual>
    <collision>
      <origin xyz="0.05 1.62133e-12 0.1115" rpy="3.14159 1.5708 0"/>
      <geometry>
        <mesh filename="package://primeu_description/assets/00__2.stl"/>
      </geometry>
    </collision>
    <!-- Part 00_3 -->
    <visual>
      <origin xyz="0.05 0.07 0.131" rpy="3.14159 1.5708 0"/>
      <geometry>
        <mesh filename="package://primeu_description/assets/00.stl"/>
      </geometry>
      <material name="00_3_material">
        <color rgba="0.231373 0.380392 0.705882 1"/>
      </material>
    </visual>
    <collision>
      <origin xyz="0.05 0.07 0.131" rpy="3.14159 1.5708 0"/>
      <geometry>
        <mesh filename="package://primeu_description/assets/00.stl"/>
      </geometry>
    </collision>
    <!-- Part neck_case -->
    <visual>
      <origin xyz="0.104473 0.0556108 -0.361408" rpy="1.18892 -1.56823 -1.17259"/>
      <geometry>
        <mesh filename="package://primeu_description/assets/neck_case.stl"/>
      </geometry>
      <material name="neck_case_material">
        <color rgba="0.972549 0.529412 0.00392157 1"/>
      </material>
    </visual>
    <collision>
      <origin xyz="0.104473 0.0556108 -0.361408" rpy="1.18892 -1.56823 -1.17259"/>
      <geometry>
        <mesh filename="package://primeu_description/assets/neck_case.stl"/>
      </geometry>
    </collision>
    <!-- Part bearing_10_22_6_3 -->
    <visual>
      <origin xyz="0 0 -0.003" rpy="-1.26957e-30 -6.59456e-31 3.45127e-31"/>
      <geometry>
        <mesh filename="package://primeu_description/assets/bearing_10_22_6.stl"/>
      </geometry>
      <material name="bearing_10_22_6_3_material">
        <color rgba="0.231373 0.380392 0.705882 1"/>
      </material>
    </visual>
    <collision>
      <origin xyz="0 0 -0.003" rpy="-1.26957e-30 -6.59456e-31 3.45127e-31"/>
      <geometry>
        <mesh filename="package://primeu_description/assets/bearing_10_22_6.stl"/>
      </geometry>
    </collision>
    <!-- Part shoulder_left_base -->
    <visual>
      <origin xyz="0.0279176 -0.237517 0.0225193" rpy="-1.5708 1.5708 0"/>
      <geometry>
        <mesh filename="package://primeu_description/assets/shoulder_left_base.stl"/>
      </geometry>
      <material name="shoulder_left_base_material">
        <color rgba="0.980392 0.713725 0.00392157 1"/>
      </material>
    </visual>
    <collision>
      <origin xyz="0.0279176 -0.237517 0.0225193" rpy="-1.5708 1.5708 0"/>
      <geometry>
        <mesh filename="package://primeu_description/assets/shoulder_left_base.stl"/>
      </geometry>
    </collision>
    <!-- Part erob90hi_xx_18ex_v0001_2 -->
    <visual>
      <origin xyz="8.58936e-12 0.07 0.096" rpy="-3.14159 -1.5708 0"/>
      <geometry>
        <mesh filename="package://primeu_description/assets/erob90hi_xx_18ex_v0001.stl"/>
      </geometry>
      <material name="erob90hi_xx_18ex_v0001_2_material">
        <color rgba="0.615686 0.811765 0.929412 1"/>
      </material>
    </visual>
    <collision>
      <origin xyz="8.58936e-12 0.07 0.096" rpy="-3.14159 -1.5708 0"/>
      <geometry>
        <mesh filename="package://primeu_description/assets/erob90hi_xx_18ex_v0001.stl"/>
      </geometry>
    </collision>
    <!-- Part waist_motor_cover -->
    <visual>
      <origin xyz="-0.0001 0.07 0.023" rpy="-3.14159 -1.5708 0"/>
      <geometry>
        <mesh filename="package://primeu_description/assets/waist_motor_cover.stl"/>
      </geometry>
      <material name="waist_motor_cover_material">
        <color rgba="0.917647 0.917647 0.917647 1"/>
      </material>
    </visual>
    <collision>
      <origin xyz="-0.0001 0.07 0.023" rpy="-3.14159 -1.5708 0"/>
      <geometry>
        <mesh filename="package://primeu_description/assets/waist_motor_cover.stl"/>
      </geometry>
    </collision>
    <!-- Part neck_posture -->
    <visual>
      <origin xyz="0.01443 0.3 0.023" rpy="-1.11022e-16 1.5708 0"/>
      <geometry>
        <mesh filename="package://primeu_description/assets/neck_posture.stl"/>
      </geometry>
      <material name="neck_posture_material">
        <color rgba="0.980392 0.713725 0.00392157 1"/>
      </material>
    </visual>
    <collision>
      <origin xyz="0.01443 0.3 0.023" rpy="-1.11022e-16 1.5708 0"/>
      <geometry>
        <mesh filename="package://primeu_description/assets/neck_posture.stl"/>
      </geometry>
    </collision>
    <!-- Part crank_2 -->
    <visual>
      <origin xyz="8.58931e-12 0.07 0.1155" rpy="4.44089e-16 -1.5708 0"/>
      <geometry>
        <mesh filename="package://primeu_description/assets/crank.stl"/>
      </geometry>
      <material name="crank_2_material">
        <color rgba="0.615686 0.811765 0.929412 1"/>
      </material>
    </visual>
    <collision>
      <origin xyz="8.58931e-12 0.07 0.1155" rpy="4.44089e-16 -1.5708 0"/>
      <geometry>
        <mesh filename="package://primeu_description/assets/crank.stl"/>
      </geometry>
    </collision>
    <!-- Part left_thoracic_cavity -->
    <visual>
      <origin xyz="-0.0001 0.07 0.116" rpy="2.22045e-16 -1.5708 0"/>
      <geometry>
        <mesh filename="package://primeu_description/assets/left_thoracic_cavity.stl"/>
      </geometry>
      <material name="left_thoracic_cavity_material">
        <color rgba="0.647059 0.647059 0.647059 1"/>
      </material>
    </visual>
    <collision>
      <origin xyz="-0.0001 0.07 0.116" rpy="2.22045e-16 -1.5708 0"/>
      <geometry>
        <mesh filename="package://primeu_description/assets/left_thoracic_cavity.stl"/>
      </geometry>
    </collision>
    <!-- Part waist_bear_stopper_3 -->
    <visual>
      <origin xyz="4.22839e-18 -1.38778e-17 -0.0085" rpy="3.14159 1.249e-16 5.55112e-17"/>
      <geometry>
        <mesh filename="package://primeu_description/assets/waist_bear_stopper.stl"/>
      </geometry>
      <material name="waist_bear_stopper_3_material">
        <color rgba="0.647059 0.647059 0.647059 1"/>
      </material>
    </visual>
    <collision>
      <origin xyz="4.22839e-18 -1.38778e-17 -0.0085" rpy="3.14159 1.249e-16 5.55112e-17"/>
      <geometry>
        <mesh filename="package://primeu_description/assets/waist_bear_stopper.stl"/>
      </geometry>
    </collision>
    <!-- Part bolt_8_16_m6 -->
    <visual>
      <origin xyz="0.05 0.07 0.1418" rpy="-3.14159 -1.5708 0"/>
      <geometry>
        <mesh filename="package://primeu_description/assets/bolt_8_16_m6.stl"/>
      </geometry>
      <material name="bolt_8_16_m6_material">
        <color rgba="0.647059 0.647059 0.647059 1"/>
      </material>
    </visual>
    <collision>
      <origin xyz="0.05 0.07 0.1418" rpy="-3.14159 -1.5708 0"/>
      <geometry>
        <mesh filename="package://primeu_description/assets/bolt_8_16_m6.stl"/>
      </geometry>
    </collision>
    <!-- Part erob80hi_xx_18ex_v0001 -->
    <visual>
      <origin xyz="0.01443 0.236492 -0.0501069" rpy="2.96706 -4.16334e-17 3.14159"/>
      <geometry>
        <mesh filename="package://primeu_description/assets/erob80hi_xx_18ex_v0001.stl"/>
      </geometry>
      <material name="erob80hi_xx_18ex_v0001_material">
        <color rgba="0.615686 0.811765 0.929412 1"/>
      </material>
    </visual>
    <collision>
      <origin xyz="0.01443 0.236492 -0.0501069" rpy="2.96706 -4.16334e-17 3.14159"/>
      <geometry>
        <mesh filename="package://primeu_description/assets/erob80hi_xx_18ex_v0001.stl"/>
      </geometry>
    </collision>
    <!-- Part 00_4 -->
    <visual>
      <origin xyz="0.05 1.62133e-12 0.1115" rpy="3.14159 1.5708 0"/>
      <geometry>
        <mesh filename="package://primeu_description/assets/00.stl"/>
      </geometry>
      <material name="00_4_material">
        <color rgba="0.231373 0.380392 0.705882 1"/>
      </material>
    </visual>
    <collision>
      <origin xyz="0.05 1.62133e-12 0.1115" rpy="3.14159 1.5708 0"/>
      <geometry>
        <mesh filename="package://primeu_description/assets/00.stl"/>
      </geometry>
    </collision>
    <!-- Part bolt_8_16_m6_2 -->
    <visual>
      <origin xyz="0.05 1.62133e-12 0.1223" rpy="-3.14159 -1.5708 0"/>
      <geometry>
        <mesh filename="package://primeu_description/assets/bolt_8_16_m6.stl"/>
      </geometry>
      <material name="bolt_8_16_m6_2_material">
        <color rgba="0.647059 0.647059 0.647059 1"/>
      </material>
    </visual>
    <collision>
      <origin xyz="0.05 1.62133e-12 0.1223" rpy="-3.14159 -1.5708 0"/>
      <geometry>
        <mesh filename="package://primeu_description/assets/bolt_8_16_m6.stl"/>
      </geometry>
    </collision>
    <!-- Part erob90hi_xx_18ex_v0001_3 -->
    <visual>
      <origin xyz="-8.58931e-12 0.07 -0.05" rpy="3.14159 1.5708 0"/>
      <geometry>
        <mesh filename="package://primeu_description/assets/erob90hi_xx_18ex_v0001.stl"/>
      </geometry>
      <material name="erob90hi_xx_18ex_v0001_3_material">
        <color rgba="0.615686 0.811765 0.929412 1"/>
      </material>
    </visual>
    <collision>
      <origin xyz="-8.58931e-12 0.07 -0.05" rpy="3.14159 1.5708 0"/>
      <geometry>
        <mesh filename="package://primeu_description/assets/erob90hi_xx_18ex_v0001.stl"/>
      </geometry>
    </collision>
    <!-- Part body_back_cover -->
    <visual>
      <origin xyz="0.000942413 -0.237517 0.0225193" rpy="-1.5708 -1.5708 0"/>
      <geometry>
        <mesh filename="package://primeu_description/assets/body_back_cover.stl"/>
      </geometry>
      <material name="body_back_cover_material">
        <color rgba="0.768627 0.886275 0.952941 1"/>
      </material>
    </visual>
    <collision>
      <origin xyz="0.000942413 -0.237517 0.0225193" rpy="-1.5708 -1.5708 0"/>
      <geometry>
        <mesh filename="package://primeu_description/assets/body_back_cover.stl"/>
      </geometry>
    </collision>
    <!-- Part 00_5 -->
    <visual>
      <origin xyz="0.05 1.62112e-12 -0.065" rpy="3.14159 1.5708 0"/>
      <geometry>
        <mesh filename="package://primeu_description/assets/00.stl"/>
      </geometry>
      <material name="00_5_material">
        <color rgba="0.231373 0.380392 0.705882 1"/>
      </material>
    </visual>
    <collision>
      <origin xyz="0.05 1.62112e-12 -0.065" rpy="3.14159 1.5708 0"/>
      <geometry>
        <mesh filename="package://primeu_description/assets/00.stl"/>
      </geometry>
    </collision>
    <!-- Part waist_motor_base -->
    <visual>
      <origin xyz="6.0119e-17 0.07 0.098" rpy="3.14159 1.5708 0"/>
      <geometry>
        <mesh filename="package://primeu_description/assets/waist_motor_base.stl"/>
      </geometry>
      <material name="waist_motor_base_material">
        <color rgba="0.231373 0.380392 0.705882 1"/>
      </material>
    </visual>
    <collision>
      <origin xyz="6.0119e-17 0.07 0.098" rpy="3.14159 1.5708 0"/>
      <geometry>
        <mesh filename="package://primeu_description/assets/waist_motor_base.stl"/>
      </geometry>
    </collision>
    <!-- Part bearing_10_22_6_4 -->
    <visual>
      <origin xyz="3.22008e-17 8.32667e-17 0.049" rpy="-3.14159 9.71445e-17 -3.14159"/>
      <geometry>
        <mesh filename="package://primeu_description/assets/bearing_10_22_6.stl"/>
      </geometry>
      <material name="bearing_10_22_6_4_material">
        <color rgba="0.231373 0.380392 0.705882 1"/>
      </material>
    </visual>
    <collision>
      <origin xyz="3.22008e-17 8.32667e-17 0.049" rpy="-3.14159 9.71445e-17 -3.14159"/>
      <geometry>
        <mesh filename="package://primeu_description/assets/bearing_10_22_6.stl"/>
      </geometry>
    </collision>
    <!-- Part waist_motor_base_2 -->
    <visual>
      <origin xyz="2.19551e-17 0.07 -0.052" rpy="3.14159 -1.5708 0"/>
      <geometry>
        <mesh filename="package://primeu_description/assets/waist_motor_base.stl"/>
      </geometry>
      <material name="waist_motor_base_2_material">
        <color rgba="0.231373 0.380392 0.705882 1"/>
      </material>
    </visual>
    <collision>
      <origin xyz="2.19551e-17 0.07 -0.052" rpy="3.14159 -1.5708 0"/>
      <geometry>
        <mesh filename="package://primeu_description/assets/waist_motor_base.stl"/>
      </geometry>
    </collision>
    <!-- Part 00_6 -->
    <visual>
      <origin xyz="0.05 0.07 0.131" rpy="3.14159 1.5708 0"/>
      <geometry>
        <mesh filename="package://primeu_description/assets/00__2.stl"/>
      </geometry>
      <material name="00_6_material">
        <color rgba="0.917647 0.917647 0.917647 1"/>
      </material>
    </visual>
    <collision>
      <origin xyz="0.05 0.07 0.131" rpy="3.14159 1.5708 0"/>
      <geometry>
        <mesh filename="package://primeu_description/assets/00__2.stl"/>
      </geometry>
    </collision>
    <!-- Part neck_a -->
    <visual>
      <origin xyz="0.000942413 -0.237517 0.0225193" rpy="-1.5708 -1.5708 0"/>
      <geometry>
        <mesh filename="package://primeu_description/assets/neck_a.stl"/>
      </geometry>
      <material name="neck_a_material">
        <color rgba="0.498039 0.498039 0.498039 1"/>
      </material>
    </visual>
    <collision>
      <origin xyz="0.000942413 -0.237517 0.0225193" rpy="-1.5708 -1.5708 0"/>
      <geometry>
        <mesh filename="package://primeu_description/assets/neck_a.stl"/>
      </geometry>
    </collision>
    <!-- Part bolt_8_16_m6_3 -->
    <visual>
      <origin xyz="0.05 0.07 -0.0958" rpy="3.14159 1.5708 0"/>
      <geometry>
        <mesh filename="package://primeu_description/assets/bolt_8_16_m6.stl"/>
      </geometry>
      <material name="bolt_8_16_m6_3_material">
        <color rgba="0.647059 0.647059 0.647059 1"/>
      </material>
    </visual>
    <collision>
      <origin xyz="0.05 0.07 -0.0958" rpy="3.14159 1.5708 0"/>
      <geometry>
        <mesh filename="package://primeu_description/assets/bolt_8_16_m6.stl"/>
      </geometry>
    </collision>
    <!-- Part 00_7 -->
    <visual>
      <origin xyz="0.05 0.07 -0.085" rpy="3.14159 1.5708 0"/>
      <geometry>
        <mesh filename="package://primeu_description/assets/00__2.stl"/>
      </geometry>
      <material name="00_7_material">
        <color rgba="0.917647 0.917647 0.917647 1"/>
      </material>
    </visual>
    <collision>
      <origin xyz="0.05 0.07 -0.085" rpy="3.14159 1.5708 0"/>
      <geometry>
        <mesh filename="package://primeu_description/assets/00__2.stl"/>
      </geometry>
    </collision>
    <!-- Part 00_8 -->
    <visual>
      <origin xyz="0.05 1.62112e-12 -0.065" rpy="3.14159 1.5708 0"/>
      <geometry>
        <mesh filename="package://primeu_description/assets/00__2.stl"/>
      </geometry>
      <material name="00_8_material">
        <color rgba="0.917647 0.917647 0.917647 1"/>
      </material>
    </visual>
    <collision>
      <origin xyz="0.05 1.62112e-12 -0.065" rpy="3.14159 1.5708 0"/>
      <geometry>
        <mesh filename="package://primeu_description/assets/00__2.stl"/>
      </geometry>
    </collision>
    <!-- Part shoulder_motor_base_2 -->
    <visual>
      <origin xyz="0.01443 0.24 -0.07" rpy="2.22045e-16 1.5708 0"/>
      <geometry>
        <mesh filename="package://primeu_description/assets/shoulder_motor_base.stl"/>
      </geometry>
      <material name="shoulder_motor_base_2_material">
        <color rgba="0.917647 0.917647 0.917647 1"/>
      </material>
    </visual>
    <collision>
      <origin xyz="0.01443 0.24 -0.07" rpy="2.22045e-16 1.5708 0"/>
      <geometry>
        <mesh filename="package://primeu_description/assets/shoulder_motor_base.stl"/>
      </geometry>
    </collision>
    <!-- Part shoulder_right_cover -->
    <visual>
      <origin xyz="0.0279176 -0.237369 0.0234807" rpy="-1.5708 1.5708 0"/>
      <geometry>
        <mesh filename="package://primeu_description/assets/shoulder_right_cover.stl"/>
      </geometry>
      <material name="shoulder_right_cover_material">
        <color rgba="0.980392 0.713725 0.00392157 1"/>
      </material>
    </visual>
    <collision>
      <origin xyz="0.0279176 -0.237369 0.0234807" rpy="-1.5708 1.5708 0"/>
      <geometry>
        <mesh filename="package://primeu_description/assets/shoulder_right_cover.stl"/>
      </geometry>
    </collision>
    <!-- Part shoulder_left_cover -->
    <visual>
      <origin xyz="0.0279176 -0.237369 0.0225193" rpy="-1.5708 1.5708 0"/>
      <geometry>
        <mesh filename="package://primeu_description/assets/shoulder_left_cover.stl"/>
      </geometry>
      <material name="shoulder_left_cover_material">
        <color rgba="0.980392 0.713725 0.00392157 1"/>
      </material>
    </visual>
    <collision>
      <origin xyz="0.0279176 -0.237369 0.0225193" rpy="-1.5708 1.5708 0"/>
      <geometry>
        <mesh filename="package://primeu_description/assets/shoulder_left_cover.stl"/>
      </geometry>
    </collision>
    <!-- Part ta_40 -->
    <visual>
      <origin xyz="0.01443 0.3005 0.023" rpy="-1.5708 1.5708 0"/>
      <geometry>
        <mesh filename="package://primeu_description/assets/ta_40.stl"/>
      </geometry>
      <material name="ta_40_material">
        <color rgba="0.615686 0.811765 0.929412 1"/>
      </material>
    </visual>
    <collision>
      <origin xyz="0.01443 0.3005 0.023" rpy="-1.5708 1.5708 0"/>
      <geometry>
        <mesh filename="package://primeu_description/assets/ta_40.stl"/>
      </geometry>
    </collision>
    <!-- Part waist_link_2 -->
    <visual>
      <origin xyz="0.05 1.62133e-12 0.1115" rpy="3.14159 1.5708 0"/>
      <geometry>
        <mesh filename="package://primeu_description/assets/waist_link.stl"/>
      </geometry>
      <material name="waist_link_2_material">
        <color rgba="0.498039 0.498039 0.498039 1"/>
      </material>
    </visual>
    <collision>
      <origin xyz="0.05 1.62133e-12 0.1115" rpy="3.14159 1.5708 0"/>
      <geometry>
        <mesh filename="package://primeu_description/assets/waist_link.stl"/>
      </geometry>
    </collision>
    <!-- Part body_front -->
    <visual>
      <origin xyz="0.000942413 -0.237517 0.0225193" rpy="-1.5708 -1.5708 0"/>
      <geometry>
        <mesh filename="package://primeu_description/assets/body_front.stl"/>
      </geometry>
      <material name="body_front_material">
        <color rgba="0.768627 0.886275 0.952941 1"/>
      </material>
    </visual>
    <collision>
      <origin xyz="0.000942413 -0.237517 0.0225193" rpy="-1.5708 -1.5708 0"/>
      <geometry>
        <mesh filename="package://primeu_description/assets/body_front.stl"/>
      </geometry>
    </collision>
    <!-- Part erob80hi_xx_18ex_v0001_2 -->
    <visual>
      <origin xyz="0.01443 0.236492 0.0961069" rpy="-0.174533 -6.93889e-17 1.11022e-16"/>
      <geometry>
        <mesh filename="package://primeu_description/assets/erob80hi_xx_18ex_v0001.stl"/>
      </geometry>
      <material name="erob80hi_xx_18ex_v0001_2_material">
        <color rgba="0.615686 0.811765 0.929412 1"/>
      </material>
    </visual>
    <collision>
      <origin xyz="0.01443 0.236492 0.0961069" rpy="-0.174533 -6.93889e-17 1.11022e-16"/>
      <geometry>
        <mesh filename="package://primeu_description/assets/erob80hi_xx_18ex_v0001.stl"/>
      </geometry>
    </collision>
    <!-- Part bolt_8_16_m6_4 -->
    <visual>
      <origin xyz="0.05 1.62111e-12 -0.0758" rpy="3.14159 1.5708 0"/>
      <geometry>
        <mesh filename="package://primeu_description/assets/bolt_8_16_m6.stl"/>
      </geometry>
      <material name="bolt_8_16_m6_4_material">
        <color rgba="0.647059 0.647059 0.647059 1"/>
      </material>
    </visual>
    <collision>
      <origin xyz="0.05 1.62111e-12 -0.0758" rpy="3.14159 1.5708 0"/>
      <geometry>
        <mesh filename="package://primeu_description/assets/bolt_8_16_m6.stl"/>
      </geometry>
    </collision>
    <!-- Part waist_bear_stopper_4 -->
    <visual>
      <origin xyz="1.40946e-17 6.93889e-17 0.0545" rpy="1.94289e-16 -1.66533e-16 2.22045e-16"/>
      <geometry>
        <mesh filename="package://primeu_description/assets/waist_bear_stopper.stl"/>
      </geometry>
      <material name="waist_bear_stopper_4_material">
        <color rgba="0.647059 0.647059 0.647059 1"/>
      </material>
    </visual>
    <collision>
      <origin xyz="1.40946e-17 6.93889e-17 0.0545" rpy="1.94289e-16 -1.66533e-16 2.22045e-16"/>
      <geometry>
        <mesh filename="package://primeu_description/assets/waist_bear_stopper.stl"/>
      </geometry>
    </collision>
  </link>
  <!-- Link arm_left_shoulder_pitch_link__configuration -->
  <link name="arm_left_shoulder_pitch_link__configuration">
    <inertial>
      <origin xyz="0.00568133 0.000623373 0.0557181" rpy="0 0 0"/>
      <mass value="1.68903"/>
      <inertia ixx="0.00200404" ixy="1.53614e-06" ixz="-3.98895e-05" iyy="0.00177396" iyz="2.93788e-05" izz="0.00156336"/>
    </inertial>
    <!-- Part shoulder_upper_motor_base -->
    <visual>
      <origin xyz="-8.79852e-15 4.96825e-15 0.06" rpy="1.5708 3.23005e-14 -1.5708"/>
      <geometry>
        <mesh filename="package://primeu_description/assets/shoulder_upper_motor_base.stl"/>
      </geometry>
      <material name="shoulder_upper_motor_base_material">
        <color rgba="0.917647 0.917647 0.917647 1"/>
      </material>
    </visual>
    <collision>
      <origin xyz="-8.79852e-15 4.96825e-15 0.06" rpy="1.5708 3.23005e-14 -1.5708"/>
      <geometry>
        <mesh filename="package://primeu_description/assets/shoulder_upper_motor_base.stl"/>
      </geometry>
    </collision>
    <!-- Part shoulder_motor_cover -->
    <visual>
      <origin xyz="-0.0335 -6.38378e-16 0.06" rpy="1.5708 3.23005e-14 -1.5708"/>
      <geometry>
        <mesh filename="package://primeu_description/assets/shoulder_motor_cover.stl"/>
      </geometry>
      <material name="shoulder_motor_cover_material">
        <color rgba="0.498039 0.498039 0.498039 1"/>
      </material>
    </visual>
    <collision>
      <origin xyz="-0.0335 -6.38378e-16 0.06" rpy="1.5708 3.23005e-14 -1.5708"/>
      <geometry>
        <mesh filename="package://primeu_description/assets/shoulder_motor_cover.stl"/>
      </geometry>
    </collision>
    <!-- Part erob80hi_xx_18ex_v0001_3 -->
    <visual>
      <origin xyz="-0.0212 2.85882e-15 0.06" rpy="1.5708 -2.17521e-14 1.5708"/>
      <geometry>
        <mesh filename="package://primeu_description/assets/erob80hi_xx_18ex_v0001.stl"/>
      </geometry>
      <material name="erob80hi_xx_18ex_v0001_3_material">
        <color rgba="0.615686 0.811765 0.929412 1"/>
      </material>
    </visual>
    <collision>
      <origin xyz="-0.0212 2.85882e-15 0.06" rpy="1.5708 -2.17521e-14 1.5708"/>
      <geometry>
        <mesh filename="package://primeu_description/assets/erob80hi_xx_18ex_v0001.stl"/>
      </geometry>
    </collision>
    <!-- Part arm_shoulder_case_b -->
    <visual>
      <origin xyz="-0.0151701 -0.32358 -0.195496" rpy="1.5708 -1.39626 -1.57277"/>
      <geometry>
        <mesh filename="package://primeu_description/assets/arm_shoulder_case_b.stl"/>
      </geometry>
      <material name="arm_shoulder_case_b_material">
        <color rgba="0.972549 0.529412 0.00392157 1"/>
      </material>
    </visual>
    <collision>
      <origin xyz="-0.0151701 -0.32358 -0.195496" rpy="1.5708 -1.39626 -1.57277"/>
      <geometry>
        <mesh filename="package://primeu_description/assets/arm_shoulder_case_b.stl"/>
      </geometry>
    </collision>
    <!-- Part shoulder_upper_stopper_base -->
    <visual>
      <origin xyz="0.0345 1.1352e-14 0.06" rpy="-2.25212e-13 1.5708 0"/>
      <geometry>
        <mesh filename="package://primeu_description/assets/shoulder_upper_stopper_base.stl"/>
      </geometry>
      <material name="shoulder_upper_stopper_base_material">
        <color rgba="0.615686 0.811765 0.929412 1"/>
      </material>
    </visual>
    <collision>
      <origin xyz="0.0345 1.1352e-14 0.06" rpy="-2.25212e-13 1.5708 0"/>
      <geometry>
        <mesh filename="package://primeu_description/assets/shoulder_upper_stopper_base.stl"/>
      </geometry>
    </collision>
    <!-- Part shoulder_stopper_teech -->
    <visual>
      <origin xyz="-2.77556e-17 2.77556e-17 0.006" rpy="4.20813e-14 -1.5708 0"/>
      <geometry>
        <mesh filename="package://primeu_description/assets/shoulder_stopper_teech.stl"/>
      </geometry>
      <material name="shoulder_stopper_teech_material">
        <color rgba="0.647059 0.647059 0.647059 1"/>
      </material>
    </visual>
    <collision>
      <origin xyz="-2.77556e-17 2.77556e-17 0.006" rpy="4.20813e-14 -1.5708 0"/>
      <geometry>
        <mesh filename="package://primeu_description/assets/shoulder_stopper_teech.stl"/>
      </geometry>
    </collision>
    <!-- Part bearing_40_51_5 -->
    <visual>
      <origin xyz="-0.0385 -9.15934e-16 0.06" rpy="1.5708 -2.18894e-14 1.5708"/>
      <geometry>
        <mesh filename="package://primeu_description/assets/bearing_40_51_5.stl"/>
      </geometry>
      <material name="bearing_40_51_5_material">
        <color rgba="0.972549 0.529412 0.00392157 1"/>
      </material>
    </visual>
    <collision>
      <origin xyz="-0.0385 -9.15934e-16 0.06" rpy="1.5708 -2.18894e-14 1.5708"/>
      <geometry>
        <mesh filename="package://primeu_description/assets/bearing_40_51_5.stl"/>
      </geometry>
    </collision>
    <!-- Part arm_shoulder_case_a -->
    <visual>
      <origin xyz="-0.0151701 -0.32358 -0.195496" rpy="1.5708 -1.39626 -1.57277"/>
      <geometry>
        <mesh filename="package://primeu_description/assets/arm_shoulder_case_a.stl"/>
      </geometry>
      <material name="arm_shoulder_case_a_material">
        <color rgba="0.231373 0.380392 0.705882 1"/>
      </material>
    </visual>
    <collision>
      <origin xyz="-0.0151701 -0.32358 -0.195496" rpy="1.5708 -1.39626 -1.57277"/>
      <geometry>
        <mesh filename="package://primeu_description/assets/arm_shoulder_case_a.stl"/>
      </geometry>
    </collision>
    <!-- Part shoulder_body_rack -->
    <visual>
      <origin xyz="-2.77556e-17 2.77556e-17 0.006" rpy="-1.5708 -1.5708 0"/>
      <geometry>
        <mesh filename="package://primeu_description/assets/shoulder_body_rack.stl"/>
      </geometry>
      <material name="shoulder_body_rack_material">
        <color rgba="0.615686 0.811765 0.929412 1"/>
      </material>
    </visual>
    <collision>
      <origin xyz="-2.77556e-17 2.77556e-17 0.006" rpy="-1.5708 -1.5708 0"/>
      <geometry>
        <mesh filename="package://primeu_description/assets/shoulder_body_rack.stl"/>
      </geometry>
    </collision>
  </link>
  <!-- Link arm_left_shoulder_roll_link__configuration_default -->
  <link name="arm_left_shoulder_roll_link__configuration_default">
    <inertial>
      <origin xyz="-0.101516 0.0280665 0.0411135" rpy="0 0 0"/>
      <mass value="1.43306"/>
      <inertia ixx="0.00165868" ixy="0.000383397" ixz="-2.89169e-06" iyy="0.0032945" iyz="9.3089e-07" izz="0.00311149"/>
    </inertial>
    <!-- Part arm_upper_case_a -->
    <visual>
      <origin xyz="-0.37871 -0.163034 0.02647" rpy="3.14159 -2.63609e-13 1.48353"/>
      <geometry>
        <mesh filename="package://primeu_description/assets/arm_upper_case_a.stl"/>
      </geometry>
      <material name="arm_upper_case_a_material">
        <color rgba="0.615686 0.811765 0.929412 1"/>
      </material>
    </visual>
    <collision>
      <origin xyz="-0.37871 -0.163034 0.02647" rpy="3.14159 -2.63609e-13 1.48353"/>
      <geometry>
        <mesh filename="package://primeu_description/assets/arm_upper_case_a.stl"/>
      </geometry>
    </collision>
    <!-- Part erob70hi_xx_18ex_v0001 -->
    <visual>
      <origin xyz="-0.145106 0.0388811 0.041" rpy="-1.5708 3.72243e-14 -0.261799"/>
      <geometry>
        <mesh filename="package://primeu_description/assets/erob70hi_xx_18ex_v0001.stl"/>
      </geometry>
      <material name="erob70hi_xx_18ex_v0001_material">
        <color rgba="0.498039 0.498039 0.498039 1"/>
      </material>
    </visual>
    <collision>
      <origin xyz="-0.145106 0.0388811 0.041" rpy="-1.5708 3.72243e-14 -0.261799"/>
      <geometry>
        <mesh filename="package://primeu_description/assets/erob70hi_xx_18ex_v0001.stl"/>
      </geometry>
    </collision>
    <!-- Part arm_upper_case_b -->
    <visual>
      <origin xyz="-0.37871 -0.163034 0.02647" rpy="3.14159 -2.63609e-13 1.48353"/>
      <geometry>
        <mesh filename="package://primeu_description/assets/arm_upper_case_b.stl"/>
      </geometry>
      <material name="arm_upper_case_b_material">
        <color rgba="0.231373 0.380392 0.705882 1"/>
      </material>
    </visual>
    <collision>
      <origin xyz="-0.37871 -0.163034 0.02647" rpy="3.14159 -2.63609e-13 1.48353"/>
      <geometry>
        <mesh filename="package://primeu_description/assets/arm_upper_case_b.stl"/>
      </geometry>
    </collision>
    <!-- Part upper_motor_base -->
    <visual>
      <origin xyz="-0.147787 0.0395993 0.041" rpy="-3.14159 -4.71521e-14 1.309"/>
      <geometry>
        <mesh filename="package://primeu_description/assets/upper_motor_base.stl"/>
      </geometry>
      <material name="upper_motor_base_material">
        <color rgba="0.231373 0.380392 0.705882 1"/>
      </material>
    </visual>
    <collision>
      <origin xyz="-0.147787 0.0395993 0.041" rpy="-3.14159 -4.71521e-14 1.309"/>
      <geometry>
        <mesh filename="package://primeu_description/assets/upper_motor_base.stl"/>
      </geometry>
    </collision>
    <!-- Part shoulder_idle -->
    <visual>
      <origin xyz="1.19904e-14 -1.58207e-14 0.087" rpy="3.14159 -2.6894e-15 -0.261799"/>
      <geometry>
        <mesh filename="package://primeu_description/assets/shoulder_idle.stl"/>
      </geometry>
      <material name="shoulder_idle_material">
        <color rgba="0.768627 0.886275 0.952941 1"/>
      </material>
    </visual>
    <collision>
      <origin xyz="1.19904e-14 -1.58207e-14 0.087" rpy="3.14159 -2.6894e-15 -0.261799"/>
      <geometry>
        <mesh filename="package://primeu_description/assets/shoulder_idle.stl"/>
      </geometry>
    </collision>
    <!-- Part shoulder_drive -->
    <visual>
      <origin xyz="-2.77556e-17 0 -0.005" rpy="3.14159 -2.6894e-15 -0.261799"/>
      <geometry>
        <mesh filename="package://primeu_description/assets/shoulder_drive.stl"/>
      </geometry>
      <material name="shoulder_drive_material">
        <color rgba="0.980392 0.713725 0.00392157 1"/>
      </material>
    </visual>
    <collision>
      <origin xyz="-2.77556e-17 0 -0.005" rpy="3.14159 -2.6894e-15 -0.261799"/>
      <geometry>
        <mesh filename="package://primeu_description/assets/shoulder_drive.stl"/>
      </geometry>
    </collision>
    <!-- Part upper_stopper_base -->
    <visual>
      <origin xyz="-0.147787 0.0395993 0.041" rpy="3.14159 -3.30047e-14 -1.8326"/>
      <geometry>
        <mesh filename="package://primeu_description/assets/upper_stopper_base.stl"/>
      </geometry>
      <material name="upper_stopper_base_material">
        <color rgba="0.980392 0.713725 0.00392157 1"/>
      </material>
    </visual>
    <collision>
      <origin xyz="-0.147787 0.0395993 0.041" rpy="3.14159 -3.30047e-14 -1.8326"/>
      <geometry>
        <mesh filename="package://primeu_description/assets/upper_stopper_base.stl"/>
      </geometry>
    </collision>
  </link>
  <!-- Link arm_left_shoulder_yaw_link__configuration -->
  <link name="arm_left_shoulder_yaw_link__configuration">
    <inertial>
      <origin xyz="0.00138845 0.00135998 0.0945808" rpy="0 0 0"/>
      <mass value="1.40666"/>
      <inertia ixx="0.0025112" ixy="5.4129e-07" ixz="-2.553e-05" iyy="0.00250612" iyz="7.03283e-05" izz="0.001038"/>
    </inertial>
    <!-- Part arm_upper_eblow_case_a -->
    <visual>
      <origin xyz="0.255496 -0.01453 0.163553" rpy="-1.5708 -0.174533 3.14159"/>
      <geometry>
        <mesh filename="package://primeu_description/assets/arm_upper_eblow_case_a.stl"/>
      </geometry>
      <material name="arm_upper_eblow_case_a_material">
        <color rgba="0.392157 0.392157 0.392157 1"/>
      </material>
    </visual>
    <collision>
      <origin xyz="0.255496 -0.01453 0.163553" rpy="-1.5708 -0.174533 3.14159"/>
      <geometry>
        <mesh filename="package://primeu_description/assets/arm_upper_eblow_case_a.stl"/>
      </geometry>
    </collision>
    <!-- Part elbow_upper_motor_base -->
    <visual>
      <origin xyz="0 2.77556e-16 0.11" rpy="-1.5708 3.78562e-16 -3.14159"/>
      <geometry>
        <mesh filename="package://primeu_description/assets/elbow_upper_motor_base.stl"/>
      </geometry>
      <material name="elbow_upper_motor_base_material">
        <color rgba="0.615686 0.811765 0.929412 1"/>
      </material>
    </visual>
    <collision>
      <origin xyz="0 2.77556e-16 0.11" rpy="-1.5708 3.78562e-16 -3.14159"/>
      <geometry>
        <mesh filename="package://primeu_description/assets/elbow_upper_motor_base.stl"/>
      </geometry>
    </collision>
    <!-- Part elbow_motor_cover -->
    <visual>
      <origin xyz="-0.0305 3.05311e-16 0.11" rpy="1.5708 3.12377e-17 -1.5708"/>
      <geometry>
        <mesh filename="package://primeu_description/assets/elbow_motor_cover.stl"/>
      </geometry>
      <material name="elbow_motor_cover_material">
        <color rgba="0.647059 0.647059 0.647059 1"/>
      </material>
    </visual>
    <collision>
      <origin xyz="-0.0305 3.05311e-16 0.11" rpy="1.5708 3.12377e-17 -1.5708"/>
      <geometry>
        <mesh filename="package://primeu_description/assets/elbow_motor_cover.stl"/>
      </geometry>
    </collision>
    <!-- Part upper_stopper_teech -->
    <visual>
      <origin xyz="0 2.22045e-16 0.007" rpy="-1.5708 -4.26984e-16 -3.08478e-17"/>
      <geometry>
        <mesh filename="package://primeu_description/assets/upper_stopper_teech.stl"/>
      </geometry>
      <material name="upper_stopper_teech_material">
        <color rgba="0.498039 0.498039 0.498039 1"/>
      </material>
    </visual>
    <collision>
      <origin xyz="0 2.22045e-16 0.007" rpy="-1.5708 -4.26984e-16 -3.08478e-17"/>
      <geometry>
        <mesh filename="package://primeu_description/assets/upper_stopper_teech.stl"/>
      </geometry>
    </collision>
    <!-- Part erob70hi_xx_18ex_v0001_2 -->
    <visual>
      <origin xyz="0.030725 2.77556e-16 0.11" rpy="1.5708 2.04342e-16 -3.14159"/>
      <geometry>
        <mesh filename="package://primeu_description/assets/erob70hi_xx_18ex_v0001.stl"/>
      </geometry>
      <material name="erob70hi_xx_18ex_v0001_2_material">
        <color rgba="0.498039 0.498039 0.498039 1"/>
      </material>
    </visual>
    <collision>
      <origin xyz="0.030725 2.77556e-16 0.11" rpy="1.5708 2.04342e-16 -3.14159"/>
      <geometry>
        <mesh filename="package://primeu_description/assets/erob70hi_xx_18ex_v0001.stl"/>
      </geometry>
    </collision>
    <!-- Part elbow_stopper_base -->
    <visual>
      <origin xyz="0.0335 1.22125e-15 0.11" rpy="-1.5708 4.42186e-17 -1.5708"/>
      <geometry>
        <mesh filename="package://primeu_description/assets/elbow_stopper_base.stl"/>
      </geometry>
      <material name="elbow_stopper_base_material">
        <color rgba="0.972549 0.529412 0.00392157 1"/>
      </material>
    </visual>
    <collision>
      <origin xyz="0.0335 1.22125e-15 0.11" rpy="-1.5708 4.42186e-17 -1.5708"/>
      <geometry>
        <mesh filename="package://primeu_description/assets/elbow_stopper_base.stl"/>
      </geometry>
    </collision>
    <!-- Part arm_upper_eblow_case_b -->
    <visual>
      <origin xyz="0.255496 -0.01453 0.163553" rpy="-1.5708 -0.174533 3.14159"/>
      <geometry>
        <mesh filename="package://primeu_description/assets/arm_upper_eblow_case_b.stl"/>
      </geometry>
      <material name="arm_upper_eblow_case_b_material">
        <color rgba="0.392157 0.392157 0.392157 1"/>
      </material>
    </visual>
    <collision>
      <origin xyz="0.255496 -0.01453 0.163553" rpy="-1.5708 -0.174533 3.14159"/>
      <geometry>
        <mesh filename="package://primeu_description/assets/arm_upper_eblow_case_b.stl"/>
      </geometry>
    </collision>
    <!-- Part elbow_lower_rack -->
    <visual>
      <origin xyz="0 5.55112e-17 0.007" rpy="1.5708 -3.072e-17 -2.08314e-18"/>
      <geometry>
        <mesh filename="package://primeu_description/assets/elbow_lower_rack.stl"/>
      </geometry>
      <material name="elbow_lower_rack_material">
        <color rgba="0.615686 0.811765 0.929412 1"/>
      </material>
    </visual>
    <collision>
      <origin xyz="0 5.55112e-17 0.007" rpy="1.5708 -3.072e-17 -2.08314e-18"/>
      <geometry>
        <mesh filename="package://primeu_description/assets/elbow_lower_rack.stl"/>
      </geometry>
    </collision>
    <!-- Part bearing_20_31_5 -->
    <visual>
      <origin xyz="-0.037 2.77556e-16 0.11" rpy="1.5708 -1.95474e-15 -6.93045e-16"/>
      <geometry>
        <mesh filename="package://primeu_description/assets/bearing_20_31_5.stl"/>
      </geometry>
      <material name="bearing_20_31_5_material">
        <color rgba="0.615686 0.811765 0.929412 1"/>
      </material>
    </visual>
    <collision>
      <origin xyz="-0.037 2.77556e-16 0.11" rpy="1.5708 -1.95474e-15 -6.93045e-16"/>
      <geometry>
        <mesh filename="package://primeu_description/assets/bearing_20_31_5.stl"/>
      </geometry>
    </collision>
  </link>
  <!-- Link arm_left_elbow_pitch_link__configuration -->
  <link name="arm_left_elbow_pitch_link__configuration">
    <inertial>
      <origin xyz="0.0310747 0.07302 0.0397515" rpy="0 0 0"/>
      <mass value="1.27259"/>
      <inertia ixx="0.0015463" ixy="-0.000146398" ixz="1.08497e-05" iyy="0.00118664" iyz="2.60879e-05" izz="0.00147129"/>
    </inertial>
    <!-- Part arm_elbow_lower_case_b -->
    <visual>
      <origin xyz="0.00709 0.0550896 0.294997" rpy="-1.5708 1.39626 1.1781"/>
      <geometry>
        <mesh filename="package://primeu_description/assets/arm_elbow_lower_case_b.stl"/>
      </geometry>
      <material name="arm_elbow_lower_case_b_material">
        <color rgba="0.498039 0.498039 0.498039 1"/>
      </material>
    </visual>
    <collision>
      <origin xyz="0.00709 0.0550896 0.294997" rpy="-1.5708 1.39626 1.1781"/>
      <geometry>
        <mesh filename="package://primeu_description/assets/arm_elbow_lower_case_b.stl"/>
      </geometry>
    </collision>
    <!-- Part arm_elbow_lower_case_a -->
    <visual>
      <origin xyz="0.00709 0.0550896 0.294997" rpy="-1.5708 1.39626 1.1781"/>
      <geometry>
        <mesh filename="package://primeu_description/assets/arm_elbow_lower_case_a.stl"/>
      </geometry>
      <material name="arm_elbow_lower_case_a_material">
        <color rgba="0.498039 0.498039 0.498039 1"/>
      </material>
    </visual>
    <collision>
      <origin xyz="0.00709 0.0550896 0.294997" rpy="-1.5708 1.39626 1.1781"/>
      <geometry>
        <mesh filename="package://primeu_description/assets/arm_elbow_lower_case_a.stl"/>
      </geometry>
    </collision>
    <!-- Part elbow_lower_idle -->
    <visual>
      <origin xyz="-1.45652e-06 6.0331e-07 0.0830016" rpy="-2.74889 1.5708 0"/>
      <geometry>
        <mesh filename="package://primeu_description/assets/elbow_lower_idle.stl"/>
      </geometry>
      <material name="elbow_lower_idle_material">
        <color rgba="0.980392 0.713725 0.00392157 1"/>
      </material>
    </visual>
    <collision>
      <origin xyz="-1.45652e-06 6.0331e-07 0.0830016" rpy="-2.74889 1.5708 0"/>
      <geometry>
        <mesh filename="package://primeu_description/assets/elbow_lower_idle.stl"/>
      </geometry>
    </collision>
    <!-- Part lower_stopper_base -->
    <visual>
      <origin xyz="0.0447725 0.108095 0.0395016" rpy="-0.392699 -1.5708 0"/>
      <geometry>
        <mesh filename="package://primeu_description/assets/lower_stopper_base.stl"/>
      </geometry>
      <material name="lower_stopper_base_material">
        <color rgba="0.768627 0.886275 0.952941 1"/>
      </material>
    </visual>
    <collision>
      <origin xyz="0.0447725 0.108095 0.0395016" rpy="-0.392699 -1.5708 0"/>
      <geometry>
        <mesh filename="package://primeu_description/assets/lower_stopper_base.stl"/>
      </geometry>
    </collision>
    <!-- Part elbow_lower_drive -->
    <visual>
      <origin xyz="-1.38778e-17 2.77556e-17 -0.004" rpy="-2.74889 1.5708 0"/>
      <geometry>
        <mesh filename="package://primeu_description/assets/elbow_lower_drive.stl"/>
      </geometry>
      <material name="elbow_lower_drive_material">
        <color rgba="0.615686 0.811765 0.929412 1"/>
      </material>
    </visual>
    <collision>
      <origin xyz="-1.38778e-17 2.77556e-17 -0.004" rpy="-2.74889 1.5708 0"/>
      <geometry>
        <mesh filename="package://primeu_description/assets/elbow_lower_drive.stl"/>
      </geometry>
    </collision>
    <!-- Part erob70hi_xx_18ex_v0001_3 -->
    <visual>
      <origin xyz="0.0437106 0.105531 0.0395016" rpy="-3.14159 4.15146e-16 -1.9635"/>
      <geometry>
        <mesh filename="package://primeu_description/assets/erob70hi_xx_18ex_v0001.stl"/>
      </geometry>
      <material name="erob70hi_xx_18ex_v0001_3_material">
        <color rgba="0.498039 0.498039 0.498039 1"/>
      </material>
    </visual>
    <collision>
      <origin xyz="0.0437106 0.105531 0.0395016" rpy="-3.14159 4.15146e-16 -1.9635"/>
      <geometry>
        <mesh filename="package://primeu_description/assets/erob70hi_xx_18ex_v0001.stl"/>
      </geometry>
    </collision>
    <!-- Part elbow_lower -->
    <visual>
      <origin xyz="0.0447725 0.108095 0.0395016" rpy="-2.74889 1.5708 0"/>
      <geometry>
        <mesh filename="package://primeu_description/assets/elbow_lower.stl"/>
      </geometry>
      <material name="elbow_lower_material">
        <color rgba="0.647059 0.647059 0.647059 1"/>
      </material>
    </visual>
    <collision>
      <origin xyz="0.0447725 0.108095 0.0395016" rpy="-2.74889 1.5708 0"/>
      <geometry>
        <mesh filename="package://primeu_description/assets/elbow_lower.stl"/>
      </geometry>
    </collision>
  </link>
  <!-- Link arm_left_elbow_roll_link__configuration -->
  <link name="arm_left_elbow_roll_link__configuration">
    <inertial>
      <origin xyz="5.6873e-05 -1.05768e-05 -0.0388372" rpy="0 0 0"/>
      <mass value="0.497124"/>
      <inertia ixx="0.000603171" ixy="-3.8874e-08" ixz="1.12203e-07" iyy="0.000515443" iyz="2.03315e-05" izz="0.0003437"/>
    </inertial>
    <!-- Part wrist_yaw_crank -->
    <visual>
      <origin xyz="1.59595e-16 0.02955 -0.039" rpy="1.5708 -9.24747e-16 3.14159"/>
      <geometry>
        <mesh filename="package://primeu_description/assets/wrist_yaw_crank.stl"/>
      </geometry>
      <material name="wrist_yaw_crank_material">
        <color rgba="0.498039 0.498039 0.498039 1"/>
      </material>
    </visual>
    <collision>
      <origin xyz="1.59595e-16 0.02955 -0.039" rpy="1.5708 -9.24747e-16 3.14159"/>
      <geometry>
        <mesh filename="package://primeu_description/assets/wrist_yaw_crank.stl"/>
      </geometry>
    </collision>
    <!-- Part ta_40_2 -->
    <visual>
      <origin xyz="-1.31839e-16 -0.0305 -0.039" rpy="1.5708 -8.79989e-16 3.14159"/>
      <geometry>
        <mesh filename="package://primeu_description/assets/ta_40__2.stl"/>
      </geometry>
      <material name="ta_40_2_material">
        <color rgba="0.615686 0.811765 0.929412 1"/>
      </material>
    </visual>
    <collision>
      <origin xyz="-1.31839e-16 -0.0305 -0.039" rpy="1.5708 -8.79989e-16 3.14159"/>
      <geometry>
        <mesh filename="package://primeu_description/assets/ta_40__2.stl"/>
      </geometry>
    </collision>
    <!-- Part wrist_rack_bottom -->
    <visual>
      <origin xyz="-7.63278e-17 -0.023 -0.039" rpy="1.5708 -8.69236e-16 3.14159"/>
      <geometry>
        <mesh filename="package://primeu_description/assets/wrist_rack_bottom.stl"/>
      </geometry>
      <material name="wrist_rack_bottom_material">
        <color rgba="0.615686 0.811765 0.929412 1"/>
      </material>
    </visual>
    <collision>
      <origin xyz="-7.63278e-17 -0.023 -0.039" rpy="1.5708 -8.69236e-16 3.14159"/>
      <geometry>
        <mesh filename="package://primeu_description/assets/wrist_rack_bottom.stl"/>
      </geometry>
    </collision>
    <!-- Part arm_lower_wrist_case_a -->
    <visual>
      <origin xyz="0.01453 -0.255496 0.0703906" rpy="1.5708 0.174533 1.5708"/>
      <geometry>
        <mesh filename="package://primeu_description/assets/arm_lower_wrist_case_a.stl"/>
      </geometry>
      <material name="arm_lower_wrist_case_a_material">
        <color rgba="0.917647 0.917647 0.917647 1"/>
      </material>
    </visual>
    <collision>
      <origin xyz="0.01453 -0.255496 0.0703906" rpy="1.5708 0.174533 1.5708"/>
      <geometry>
        <mesh filename="package://primeu_description/assets/arm_lower_wrist_case_a.stl"/>
      </geometry>
    </collision>
    <!-- Part bearing_30_37_4 -->
    <visual>
      <origin xyz="-7.97973e-17 -0.024 -0.099" rpy="1.5708 -8.79989e-16 3.14159"/>
      <geometry>
        <mesh filename="package://primeu_description/assets/bearing_30_37_4.stl"/>
      </geometry>
      <material name="bearing_30_37_4_material">
        <color rgba="0.768627 0.886275 0.952941 1"/>
      </material>
    </visual>
    <collision>
      <origin xyz="-7.97973e-17 -0.024 -0.099" rpy="1.5708 -8.79989e-16 3.14159"/>
      <geometry>
        <mesh filename="package://primeu_description/assets/bearing_30_37_4.stl"/>
      </geometry>
    </collision>
    <!-- Part wrist_rack_front -->
    <visual>
      <origin xyz="-6.93889e-17 0.023 -0.039" rpy="1.5708 -9.24747e-16 3.14159"/>
      <geometry>
        <mesh filename="package://primeu_description/assets/wrist_rack_front.stl"/>
      </geometry>
      <material name="wrist_rack_front_material">
        <color rgba="0.231373 0.380392 0.705882 1"/>
      </material>
    </visual>
    <collision>
      <origin xyz="-6.93889e-17 0.023 -0.039" rpy="1.5708 -9.24747e-16 3.14159"/>
      <geometry>
        <mesh filename="package://primeu_description/assets/wrist_rack_front.stl"/>
      </geometry>
    </collision>
    <!-- Part elbow_lower_rack_2 -->
    <visual>
      <origin xyz="1.04083e-17 5.55112e-17 -0.007" rpy="-1.5708 -7.44534e-17 -3.76474e-16"/>
      <geometry>
        <mesh filename="package://primeu_description/assets/elbow_lower_rack.stl"/>
      </geometry>
      <material name="elbow_lower_rack_2_material">
        <color rgba="0.615686 0.811765 0.929412 1"/>
      </material>
    </visual>
    <collision>
      <origin xyz="1.04083e-17 5.55112e-17 -0.007" rpy="-1.5708 -7.44534e-17 -3.76474e-16"/>
      <geometry>
        <mesh filename="package://primeu_description/assets/elbow_lower_rack.stl"/>
      </geometry>
    </collision>
    <!-- Part bearing_30_37_4_2 -->
    <visual>
      <origin xyz="-8.32667e-17 0.024 -0.099" rpy="1.5708 -8.79989e-16 3.14159"/>
      <geometry>
        <mesh filename="package://primeu_description/assets/bearing_30_37_4.stl"/>
      </geometry>
      <material name="bearing_30_37_4_2_material">
        <color rgba="0.768627 0.886275 0.952941 1"/>
      </material>
    </visual>
    <collision>
      <origin xyz="-8.32667e-17 0.024 -0.099" rpy="1.5708 -8.79989e-16 3.14159"/>
      <geometry>
        <mesh filename="package://primeu_description/assets/bearing_30_37_4.stl"/>
      </geometry>
    </collision>
    <!-- Part wrist_lower_link -->
    <visual>
      <origin xyz="3.46945e-18 -1.11022e-16 -0.009" rpy="1.5708 7.62015e-17 3.14159"/>
      <geometry>
        <mesh filename="package://primeu_description/assets/wrist_lower_link.stl"/>
      </geometry>
      <material name="wrist_lower_link_material">
        <color rgba="0.980392 0.713725 0.00392157 1"/>
      </material>
    </visual>
    <collision>
      <origin xyz="3.46945e-18 -1.11022e-16 -0.009" rpy="1.5708 7.62015e-17 3.14159"/>
      <geometry>
        <mesh filename="package://primeu_description/assets/wrist_lower_link.stl"/>
      </geometry>
    </collision>
    <!-- Part wrist_link -->
    <visual>
      <origin xyz="-0.012 0.03355 -0.039" rpy="1.5708 -9.355e-16 3.14159"/>
      <geometry>
        <mesh filename="package://primeu_description/assets/wrist_link.stl"/>
      </geometry>
      <material name="wrist_link_material">
        <color rgba="0.231373 0.380392 0.705882 1"/>
      </material>
    </visual>
    <collision>
      <origin xyz="-0.012 0.03355 -0.039" rpy="1.5708 -9.355e-16 3.14159"/>
      <geometry>
        <mesh filename="package://primeu_description/assets/wrist_link.stl"/>
      </geometry>
    </collision>
    <!-- Part wrist_link_2 -->
    <visual>
      <origin xyz="0.012 0.03355 -0.039" rpy="1.5708 -9.355e-16 3.14159"/>
      <geometry>
        <mesh filename="package://primeu_description/assets/wrist_link.stl"/>
      </geometry>
      <material name="wrist_link_2_material">
        <color rgba="0.231373 0.380392 0.705882 1"/>
      </material>
    </visual>
    <collision>
      <origin xyz="0.012 0.03355 -0.039" rpy="1.5708 -9.355e-16 3.14159"/>
      <geometry>
        <mesh filename="package://primeu_description/assets/wrist_link.stl"/>
      </geometry>
    </collision>
    <!-- Part arm_lower_wrist_case_b -->
    <visual>
      <origin xyz="0.01453 -0.255496 0.0703906" rpy="1.5708 0.174533 1.5708"/>
      <geometry>
        <mesh filename="package://primeu_description/assets/arm_lower_wrist_case_b.stl"/>
      </geometry>
      <material name="arm_lower_wrist_case_b_material">
        <color rgba="0.615686 0.811765 0.929412 1"/>
      </material>
    </visual>
    <collision>
      <origin xyz="0.01453 -0.255496 0.0703906" rpy="1.5708 0.174533 1.5708"/>
      <geometry>
        <mesh filename="package://primeu_description/assets/arm_lower_wrist_case_b.stl"/>
      </geometry>
    </collision>
  </link>
  <!-- Link arm_left_elbow_yaw_link -->
  <link name="arm_left_elbow_yaw_link">
    <inertial>
      <origin xyz="-0.00106391 2.33417e-11 -0.0219286" rpy="0 0 0"/>
      <mass value="0.304398"/>
      <inertia ixx="8.08739e-05" ixy="-1.64597e-11" ixz="-5.38408e-07" iyy="0.000118571" iyz="4.41999e-12" izz="0.000107519"/>
    </inertial>
    <!-- Part gearing_front_stopper -->
    <visual>
      <origin xyz="-3.13291e-15 -8.32667e-16 0.005" rpy="-1.69866e-13 1.3407e-14 1.5708"/>
      <geometry>
        <mesh filename="package://primeu_description/assets/gearing_front_stopper.stl"/>
      </geometry>
      <material name="gearing_front_stopper_material">
        <color rgba="0.917647 0.917647 0.917647 1"/>
      </material>
    </visual>
    <collision>
      <origin xyz="-3.13291e-15 -8.32667e-16 0.005" rpy="-1.69866e-13 1.3407e-14 1.5708"/>
      <geometry>
        <mesh filename="package://primeu_description/assets/gearing_front_stopper.stl"/>
      </geometry>
    </collision>
    <!-- Part wrist_pitch_gearing_base -->
    <visual>
      <origin xyz="0.0243 3.33067e-16 -0.022" rpy="1.5708 -7.72073e-14 -3.45947e-14"/>
      <geometry>
        <mesh filename="package://primeu_description/assets/wrist_pitch_gearing_base.stl"/>
      </geometry>
      <material name="wrist_pitch_gearing_base_material">
        <color rgba="0.980392 0.713725 0.00392157 1"/>
      </material>
    </visual>
    <collision>
      <origin xyz="0.0243 3.33067e-16 -0.022" rpy="1.5708 -7.72073e-14 -3.45947e-14"/>
      <geometry>
        <mesh filename="package://primeu_description/assets/wrist_pitch_gearing_base.stl"/>
      </geometry>
    </collision>
    <!-- Part ta_40_3 -->
    <visual>
      <origin xyz="0.024 -3.16414e-15 -0.022" rpy="-1.97629e-13 -1.5708 0"/>
      <geometry>
        <mesh filename="package://primeu_description/assets/ta_40__2.stl"/>
      </geometry>
      <material name="ta_40_3_material">
        <color rgba="0.615686 0.811765 0.929412 1"/>
      </material>
    </visual>
    <collision>
      <origin xyz="0.024 -3.16414e-15 -0.022" rpy="-1.97629e-13 -1.5708 0"/>
      <geometry>
        <mesh filename="package://primeu_description/assets/ta_40__2.stl"/>
      </geometry>
    </collision>
    <!-- Part wrist_pitch_motor_base -->
    <visual>
      <origin xyz="9.71445e-17 -5.55112e-17 -0.022" rpy="5.82289e-16 -9.75369e-15 -7.26843e-16"/>
      <geometry>
        <mesh filename="package://primeu_description/assets/wrist_pitch_motor_base.stl"/>
      </geometry>
      <material name="wrist_pitch_motor_base_material">
        <color rgba="0.647059 0.647059 0.647059 1"/>
      </material>
    </visual>
    <collision>
      <origin xyz="9.71445e-17 -5.55112e-17 -0.022" rpy="5.82289e-16 -9.75369e-15 -7.26843e-16"/>
      <geometry>
        <mesh filename="package://primeu_description/assets/wrist_pitch_motor_base.stl"/>
      </geometry>
    </collision>
    <!-- Part gearing_bottom_stopper -->
    <visual>
      <origin xyz="3.92048e-16 3.44169e-15 -0.049" rpy="-4.92869e-16 -1.02364e-14 -2.1649e-16"/>
      <geometry>
        <mesh filename="package://primeu_description/assets/gearing_bottom_stopper.stl"/>
      </geometry>
      <material name="gearing_bottom_stopper_material">
        <color rgba="0.615686 0.811765 0.929412 1"/>
      </material>
    </visual>
    <collision>
      <origin xyz="3.92048e-16 3.44169e-15 -0.049" rpy="-4.92869e-16 -1.02364e-14 -2.1649e-16"/>
      <geometry>
        <mesh filename="package://primeu_description/assets/gearing_bottom_stopper.stl"/>
      </geometry>
    </collision>
  </link>
  <!-- Link arm_left_wrist_pitch_link -->
  <link name="arm_left_wrist_pitch_link">
    <inertial>
      <origin xyz="0 0 0" rpy="0 0 0"/>
      <mass value="1e-09"/>
      <inertia ixx="1e-09" ixy="0" ixz="0" iyy="1e-09" iyz="0" izz="1e-09"/>
    </inertial>
    <!-- Part wrist_connecting -->
    <visual>
      <origin xyz="3.16414e-15 0.035 0.03005" rpy="-3.14159 1.55104e-14 4.77617e-15"/>
      <geometry>
        <mesh filename="package://primeu_description/assets/wrist_connecting.stl"/>
      </geometry>
      <material name="wrist_connecting_material">
        <color rgba="0.615686 0.811765 0.929412 1"/>
      </material>
    </visual>
    <collision>
      <origin xyz="3.16414e-15 0.035 0.03005" rpy="-3.14159 1.55104e-14 4.77617e-15"/>
      <geometry>
        <mesh filename="package://primeu_description/assets/wrist_connecting.stl"/>
      </geometry>
    </collision>
    <!-- Part wrist_drive -->
    <visual>
      <origin xyz="-5.55112e-17 1.66533e-16 -0.00445" rpy="-3.14159 1.54719e-14 4.87019e-15"/>
      <geometry>
        <mesh filename="package://primeu_description/assets/wrist_drive.stl"/>
      </geometry>
      <material name="wrist_drive_material">
        <color rgba="0.647059 0.647059 0.647059 1"/>
      </material>
    </visual>
    <collision>
      <origin xyz="-5.55112e-17 1.66533e-16 -0.00445" rpy="-3.14159 1.54719e-14 4.87019e-15"/>
      <geometry>
        <mesh filename="package://primeu_description/assets/wrist_drive.stl"/>
      </geometry>
    </collision>
    <!-- Part wrist_idle -->
    <visual>
      <origin xyz="2.10942e-15 5.77316e-15 0.06455" rpy="-3.14159 8.51773e-14 -7.4055e-15"/>
      <geometry>
        <mesh filename="package://primeu_description/assets/wrist_idle.stl"/>
      </geometry>
      <material name="wrist_idle_material">
        <color rgba="0.498039 0.498039 0.498039 1"/>
      </material>
    </visual>
    <collision>
      <origin xyz="2.10942e-15 5.77316e-15 0.06455" rpy="-3.14159 8.51773e-14 -7.4055e-15"/>
      <geometry>
        <mesh filename="package://primeu_description/assets/wrist_idle.stl"/>
      </geometry>
    </collision>
  </link>
  <!-- Joint from arm_left_elbow_yaw_link to arm_left_wrist_pitch_link -->
  <joint name="arm_left_wrist_pitch_joint" type="revolute">
    <origin xyz="-0.03005 7.49401e-15 -0.022" rpy="3.14159 -1.5708 0"/>
    <parent link="arm_left_elbow_yaw_link"/>
    <child link="arm_left_wrist_pitch_link"/>
    <axis xyz="0 0 1"/>
    <limit effort="5.0" velocity="6.0" lower="-1.5708" upper="1.5708"/>
    <joint_properties friction="0.5"/>
  </joint>
  <!-- Joint from arm_left_elbow_roll_link__configuration to arm_left_elbow_yaw_link -->
  <joint name="arm_left_wrist_roll_joint" type="revolute">
    <origin xyz="-1.00614e-16 0.022 -0.099" rpy="1.5708 -8.79989e-16 3.14159"/>
    <parent link="arm_left_elbow_roll_link__configuration"/>
    <child link="arm_left_elbow_yaw_link"/>
    <axis xyz="0 0 1"/>
    <limit effort="5.0" velocity="6.0" lower="-0.785398" upper="0.785398"/>
    <joint_properties friction="0.5"/>
  </joint>
  <!-- Joint from arm_left_elbow_pitch_link__configuration to arm_left_elbow_roll_link__configuration -->
  <joint name="arm_left_wrist_yaw_joint" type="revolute">
    <origin xyz="0.0474513 0.114562 0.0395016" rpy="-1.5708 1.72392e-15 2.74889"/>
    <parent link="arm_left_elbow_pitch_link__configuration"/>
    <child link="arm_left_elbow_roll_link__configuration"/>
    <axis xyz="0 0 -1"/>
    <limit effort="5.0" velocity="6.0" lower="-1.5708" upper="1.5708"/>
    <joint_properties friction="0.5"/>
  </joint>
  <!-- Joint from arm_left_shoulder_yaw_link__configuration to arm_left_elbow_pitch_link__configuration -->
  <joint name="arm_left_elbow_pitch_joint" type="revolute">
    <origin xyz="-0.0395 2.498e-16 0.11" rpy="3.14159 -1.5708 0"/>
    <parent link="arm_left_shoulder_yaw_link__configuration"/>
    <child link="arm_left_elbow_pitch_link__configuration"/>
    <axis xyz="0 0 1"/>
    <limit effort="5" velocity="6.0" lower="-1.1781" upper="1.1781"/>
    <joint_properties friction="0.5"/>
  </joint>
  <!-- Joint from arm_left_shoulder_roll_link__configuration_default to arm_left_shoulder_yaw_link__configuration -->
  <joint name="arm_left_shoulder_yaw_joint" type="revolute">
    <origin xyz="-0.154548 0.041411 0.041" rpy="1.5708 5.39331e-14 -1.8326"/>
    <parent link="arm_left_shoulder_roll_link__configuration_default"/>
    <child link="arm_left_shoulder_yaw_link__configuration"/>
    <axis xyz="0 0 1"/>
    <limit effort="5.0" velocity="6.0" lower="-1.5708" upper="1.5708"/>
    <joint_properties friction="0.5"/>
  </joint>
  <!-- Joint from arm_left_shoulder_pitch_link__configuration to arm_left_shoulder_roll_link__configuration_default -->
  <joint name="arm_left_shoulder_roll_joint" type="revolute">
    <origin xyz="-0.041 -1.08247e-15 0.06" rpy="1.5708 -2.18894e-14 1.5708"/>
    <parent link="arm_left_shoulder_pitch_link__configuration"/>
    <child link="arm_left_shoulder_roll_link__configuration_default"/>
    <axis xyz="0 0 1"/>
    <limit effort="5.0" velocity="6.0" lower="-1.0472" upper="1.0472"/>
    <joint_properties friction="0.5"/>
  </joint>
  <!-- Joint from chest_link__configuration_default to arm_left_shoulder_pitch_link__configuration -->
  <joint name="arm_left_shoulder_pitch_joint" type="revolute">
    <origin xyz="0.01443 0.247814 0.160316" rpy="-0.124042 -0.123098 -0.777744"/>
    <parent link="chest_link__configuration_default"/>
    <child link="arm_left_shoulder_pitch_link__configuration"/>
    <axis xyz="0 0 1"/>
    <limit effort="5.0" velocity="6.0" lower="-2.35619" upper="2.35619"/>
    <joint_properties friction="0.5"/>
  </joint>
  <!-- Link arm_right_shoulder_pitch_link__configuration -->
  <link name="arm_right_shoulder_pitch_link__configuration">
    <inertial>
      <origin xyz="-0.0056818 0.00048746 0.0557988" rpy="0 0 0"/>
      <mass value="1.68895"/>
      <inertia ixx="0.00200527" ixy="-8.50686e-06" ixz="4.38589e-05" iyy="0.00177494" iyz="3.05005e-05" izz="0.00156353"/>
    </inertial>
    <!-- Part arm_shoulder_case_b_mir -->
    <visual>
      <origin xyz="0.0151701 -0.32358 -0.195496" rpy="1.5708 -1.39626 -1.56882"/>
      <geometry>
        <mesh filename="package://primeu_description/assets/arm_shoulder_case_b_mir.stl"/>
      </geometry>
      <material name="arm_shoulder_case_b_mir_material">
        <color rgba="0.917647 0.917647 0.917647 1"/>
      </material>
    </visual>
    <collision>
      <origin xyz="0.0151701 -0.32358 -0.195496" rpy="1.5708 -1.39626 -1.56882"/>
      <geometry>
        <mesh filename="package://primeu_description/assets/arm_shoulder_case_b_mir.stl"/>
      </geometry>
    </collision>
    <!-- Part shoulder_stopper_teech_mir -->
    <visual>
      <origin xyz="1.11022e-16 8.32667e-17 0.006" rpy="4.14313e-14 -1.5708 0"/>
      <geometry>
        <mesh filename="package://primeu_description/assets/shoulder_stopper_teech_mir.stl"/>
      </geometry>
      <material name="shoulder_stopper_teech_mir_material">
        <color rgba="0.972549 0.529412 0.00392157 1"/>
      </material>
    </visual>
    <collision>
      <origin xyz="1.11022e-16 8.32667e-17 0.006" rpy="4.14313e-14 -1.5708 0"/>
      <geometry>
        <mesh filename="package://primeu_description/assets/shoulder_stopper_teech_mir.stl"/>
      </geometry>
    </collision>
    <!-- Part shoulder_body_rack_mir -->
    <visual>
      <origin xyz="0 0 0.006" rpy="-1.5708 -1.5708 0"/>
      <geometry>
        <mesh filename="package://primeu_description/assets/shoulder_body_rack_mir.stl"/>
      </geometry>
      <material name="shoulder_body_rack_mir_material">
        <color rgba="0.768627 0.886275 0.952941 1"/>
      </material>
    </visual>
    <collision>
      <origin xyz="0 0 0.006" rpy="-1.5708 -1.5708 0"/>
      <geometry>
        <mesh filename="package://primeu_description/assets/shoulder_body_rack_mir.stl"/>
      </geometry>
    </collision>
    <!-- Part arm_shoulder_case_a_mir -->
    <visual>
      <origin xyz="0.0151701 -0.32358 -0.195496" rpy="1.5708 1.39626 1.57277"/>
      <geometry>
        <mesh filename="package://primeu_description/assets/arm_shoulder_case_a_mir.stl"/>
      </geometry>
      <material name="arm_shoulder_case_a_mir_material">
        <color rgba="0.231373 0.380392 0.705882 1"/>
      </material>
    </visual>
    <collision>
      <origin xyz="0.0151701 -0.32358 -0.195496" rpy="1.5708 1.39626 1.57277"/>
      <geometry>
        <mesh filename="package://primeu_description/assets/arm_shoulder_case_a_mir.stl"/>
      </geometry>
    </collision>
    <!-- Part bearing_40_51_5_mir -->
    <visual>
      <origin xyz="0.0385 -2.77556e-17 0.06" rpy="1.5708 3.06826e-15 1.5708"/>
      <geometry>
        <mesh filename="package://primeu_description/assets/bearing_40_51_5_mir.stl"/>
      </geometry>
      <material name="bearing_40_51_5_mir_material">
        <color rgba="0.647059 0.647059 0.647059 1"/>
      </material>
    </visual>
    <collision>
      <origin xyz="0.0385 -2.77556e-17 0.06" rpy="1.5708 3.06826e-15 1.5708"/>
      <geometry>
        <mesh filename="package://primeu_description/assets/bearing_40_51_5_mir.stl"/>
      </geometry>
    </collision>
    <!-- Part shoulder_motor_cover_mir -->
    <visual>
      <origin xyz="0.0335 -6.66134e-16 0.06" rpy="1.5708 6.06723e-15 -1.5708"/>
      <geometry>
        <mesh filename="package://primeu_description/assets/shoulder_motor_cover_mir.stl"/>
      </geometry>
      <material name="shoulder_motor_cover_mir_material">
        <color rgba="0.231373 0.380392 0.705882 1"/>
      </material>
    </visual>
    <collision>
      <origin xyz="0.0335 -6.66134e-16 0.06" rpy="1.5708 6.06723e-15 -1.5708"/>
      <geometry>
        <mesh filename="package://primeu_description/assets/shoulder_motor_cover_mir.stl"/>
      </geometry>
    </collision>
    <!-- Part shoulder_upper_motor_base_mir -->
    <visual>
      <origin xyz="2.13718e-15 -1.58207e-15 0.06" rpy="1.5708 -1.67275e-15 -1.5708"/>
      <geometry>
        <mesh filename="package://primeu_description/assets/shoulder_upper_motor_base_mir.stl"/>
      </geometry>
      <material name="shoulder_upper_motor_base_mir_material">
        <color rgba="0.980392 0.713725 0.00392157 1"/>
      </material>
    </visual>
    <collision>
      <origin xyz="2.13718e-15 -1.58207e-15 0.06" rpy="1.5708 -1.67275e-15 -1.5708"/>
      <geometry>
        <mesh filename="package://primeu_description/assets/shoulder_upper_motor_base_mir.stl"/>
      </geometry>
    </collision>
    <!-- Part erob80hi_xx_18ex_v0001_4 -->
    <visual>
      <origin xyz="0.0212 -1.69309e-15 0.06" rpy="1.5708 -6.70575e-15 -1.5708"/>
      <geometry>
        <mesh filename="package://primeu_description/assets/erob80hi_xx_18ex_v0001.stl"/>
      </geometry>
      <material name="erob80hi_xx_18ex_v0001_4_material">
        <color rgba="0.615686 0.811765 0.929412 1"/>
      </material>
    </visual>
    <collision>
      <origin xyz="0.0212 -1.69309e-15 0.06" rpy="1.5708 -6.70575e-15 -1.5708"/>
      <geometry>
        <mesh filename="package://primeu_description/assets/erob80hi_xx_18ex_v0001.stl"/>
      </geometry>
    </collision>
    <!-- Part shoulder_upper_stopper_base_mir -->
    <visual>
      <origin xyz="-0.0345 -1.85962e-15 0.06" rpy="3.14159 -1.5708 0"/>
      <geometry>
        <mesh filename="package://primeu_description/assets/shoulder_upper_stopper_base_mir.stl"/>
      </geometry>
      <material name="shoulder_upper_stopper_base_mir_material">
        <color rgba="0.768627 0.886275 0.952941 1"/>
      </material>
    </visual>
    <collision>
      <origin xyz="-0.0345 -1.85962e-15 0.06" rpy="3.14159 -1.5708 0"/>
      <geometry>
        <mesh filename="package://primeu_description/assets/shoulder_upper_stopper_base_mir.stl"/>
      </geometry>
    </collision>
  </link>
  <!-- Link arm_right_shoulder_roll_link__configuration_default -->
  <link name="arm_right_shoulder_roll_link__configuration_default">
    <inertial>
      <origin xyz="-0.10532 -0.000836183 0.041167" rpy="0 0 0"/>
      <mass value="1.43316"/>
      <inertia ixx="0.00157664" ixy="7.69025e-05" ixz="-4.1892e-06" iyy="0.0033766" iyz="1.24728e-07" izz="0.00311158"/>
    </inertial>
    <!-- Part shoulder_drive_mir -->
    <visual>
      <origin xyz="-2.77556e-17 0 -0.005" rpy="-2.52931e-17 -4.51454e-17 4.2026e-17"/>
      <geometry>
        <mesh filename="package://primeu_description/assets/shoulder_drive_mir.stl"/>
      </geometry>
      <material name="shoulder_drive_mir_material">
        <color rgba="0.917647 0.917647 0.917647 1"/>
      </material>
    </visual>
    <collision>
      <origin xyz="-2.77556e-17 0 -0.005" rpy="-2.52931e-17 -4.51454e-17 4.2026e-17"/>
      <geometry>
        <mesh filename="package://primeu_description/assets/shoulder_drive_mir.stl"/>
      </geometry>
    </collision>
    <!-- Part shoulder_idle_mir -->
    <visual>
      <origin xyz="5.82867e-16 1.27676e-15 0.087" rpy="-2.52931e-17 -4.51454e-17 4.2026e-17"/>
      <geometry>
        <mesh filename="package://primeu_description/assets/shoulder_idle_mir.stl"/>
      </geometry>
      <material name="shoulder_idle_mir_material">
        <color rgba="0.615686 0.811765 0.929412 1"/>
      </material>
    </visual>
    <collision>
      <origin xyz="5.82867e-16 1.27676e-15 0.087" rpy="-2.52931e-17 -4.51454e-17 4.2026e-17"/>
      <geometry>
        <mesh filename="package://primeu_description/assets/shoulder_idle_mir.stl"/>
      </geometry>
    </collision>
    <!-- Part erob70hi_xx_18ex_v0001_4 -->
    <visual>
      <origin xyz="-0.150225 -2.77556e-16 0.041" rpy="1.5708 3.10191e-14 -3.41345e-14"/>
      <geometry>
        <mesh filename="package://primeu_description/assets/erob70hi_xx_18ex_v0001.stl"/>
      </geometry>
      <material name="erob70hi_xx_18ex_v0001_4_material">
        <color rgba="0.498039 0.498039 0.498039 1"/>
      </material>
    </visual>
    <collision>
      <origin xyz="-0.150225 -2.77556e-16 0.041" rpy="1.5708 3.10191e-14 -3.41345e-14"/>
      <geometry>
        <mesh filename="package://primeu_description/assets/erob70hi_xx_18ex_v0001.stl"/>
      </geometry>
    </collision>
    <!-- Part upper_stopper_base_mir -->
    <visual>
      <origin xyz="-0.153 -1.55431e-15 0.041" rpy="1.4847e-14 3.70722e-14 1.5708"/>
      <geometry>
        <mesh filename="package://primeu_description/assets/upper_stopper_base_mir.stl"/>
      </geometry>
      <material name="upper_stopper_base_mir_material">
        <color rgba="0.917647 0.917647 0.917647 1"/>
      </material>
    </visual>
    <collision>
      <origin xyz="-0.153 -1.55431e-15 0.041" rpy="1.4847e-14 3.70722e-14 1.5708"/>
      <geometry>
        <mesh filename="package://primeu_description/assets/upper_stopper_base_mir.stl"/>
      </geometry>
    </collision>
    <!-- Part arm_upper_case_b_mir -->
    <visual>
      <origin xyz="-0.323609 0.255496 0.02647" rpy="3.84261e-15 4.48364e-13 -1.74533"/>
      <geometry>
        <mesh filename="package://primeu_description/assets/arm_upper_case_b_mir.stl"/>
      </geometry>
      <material name="arm_upper_case_b_mir_material">
        <color rgba="0.972549 0.529412 0.00392157 1"/>
      </material>
    </visual>
    <collision>
      <origin xyz="-0.323609 0.255496 0.02647" rpy="3.84261e-15 4.48364e-13 -1.74533"/>
      <geometry>
        <mesh filename="package://primeu_description/assets/arm_upper_case_b_mir.stl"/>
      </geometry>
    </collision>
    <!-- Part upper_motor_base_mir -->
    <visual>
      <origin xyz="-0.153 -1.55431e-15 0.041" rpy="-1.59076e-14 -3.83658e-14 -1.5708"/>
      <geometry>
        <mesh filename="package://primeu_description/assets/upper_motor_base_mir.stl"/>
      </geometry>
      <material name="upper_motor_base_mir_material">
        <color rgba="0.498039 0.498039 0.498039 1"/>
      </material>
    </visual>
    <collision>
      <origin xyz="-0.153 -1.55431e-15 0.041" rpy="-1.59076e-14 -3.83658e-14 -1.5708"/>
      <geometry>
        <mesh filename="package://primeu_description/assets/upper_motor_base_mir.stl"/>
      </geometry>
    </collision>
    <!-- Part arm_upper_case_a_mir -->
    <visual>
      <origin xyz="-0.323609 0.255496 0.02647" rpy="3.84261e-15 4.48364e-13 -1.74533"/>
      <geometry>
        <mesh filename="package://primeu_description/assets/arm_upper_case_a_mir.stl"/>
      </geometry>
      <material name="arm_upper_case_a_mir_material">
        <color rgba="0.917647 0.917647 0.917647 1"/>
      </material>
    </visual>
    <collision>
      <origin xyz="-0.323609 0.255496 0.02647" rpy="3.84261e-15 4.48364e-13 -1.74533"/>
      <geometry>
        <mesh filename="package://primeu_description/assets/arm_upper_case_a_mir.stl"/>
      </geometry>
    </collision>
  </link>
  <!-- Link arm_right_shoulder_yaw_link__configuration -->
  <link name="arm_right_shoulder_yaw_link__configuration">
    <inertial>
      <origin xyz="0.00136001 0.00138818 0.0945259" rpy="0 0 0"/>
      <mass value="1.40667"/>
      <inertia ixx="0.00250382" ixy="5.4095e-07" ixz="7.05517e-05" iyy="0.00250889" iyz="-2.78755e-05" izz="0.00103801"/>
    </inertial>
    <!-- Part bearing_20_31_5_mir -->
    <visual>
      <origin xyz="-1.38778e-15 -0.037 0.11" rpy="-1.5708 2.21402e-15 -1.5708"/>
      <geometry>
        <mesh filename="package://primeu_description/assets/bearing_20_31_5_mir.stl"/>
      </geometry>
      <material name="bearing_20_31_5_mir_material">
        <color rgba="0.768627 0.886275 0.952941 1"/>
      </material>
    </visual>
    <collision>
      <origin xyz="-1.38778e-15 -0.037 0.11" rpy="-1.5708 2.21402e-15 -1.5708"/>
      <geometry>
        <mesh filename="package://primeu_description/assets/bearing_20_31_5_mir.stl"/>
      </geometry>
    </collision>
    <!-- Part upper_stopper_teech_mir -->
    <visual>
      <origin xyz="2.77556e-17 -5.55112e-17 0.007" rpy="-1.5708 -2.03271e-15 1.5708"/>
      <geometry>
        <mesh filename="package://primeu_description/assets/upper_stopper_teech_mir.stl"/>
      </geometry>
      <material name="upper_stopper_teech_mir_material">
        <color rgba="0.231373 0.380392 0.705882 1"/>
      </material>
    </visual>
    <collision>
      <origin xyz="2.77556e-17 -5.55112e-17 0.007" rpy="-1.5708 -2.03271e-15 1.5708"/>
      <geometry>
        <mesh filename="package://primeu_description/assets/upper_stopper_teech_mir.stl"/>
      </geometry>
    </collision>
    <!-- Part elbow_motor_cover_mir -->
    <visual>
      <origin xyz="-1.16573e-15 -0.0305 0.11" rpy="1.5708 9.65981e-15 3.14159"/>
      <geometry>
        <mesh filename="package://primeu_description/assets/elbow_motor_cover_mir.stl"/>
      </geometry>
      <material name="elbow_motor_cover_mir_material">
        <color rgba="0.972549 0.529412 0.00392157 1"/>
      </material>
    </visual>
    <collision>
      <origin xyz="-1.16573e-15 -0.0305 0.11" rpy="1.5708 9.65981e-15 3.14159"/>
      <geometry>
        <mesh filename="package://primeu_description/assets/elbow_motor_cover_mir.stl"/>
      </geometry>
    </collision>
    <!-- Part elbow_upper_motor_base_mir -->
    <visual>
      <origin xyz="-2.77556e-17 1.11022e-16 0.11" rpy="-1.5708 2.29729e-15 -1.5708"/>
      <geometry>
        <mesh filename="package://primeu_description/assets/elbow_upper_motor_base_mir.stl"/>
      </geometry>
      <material name="elbow_upper_motor_base_mir_material">
        <color rgba="0.768627 0.886275 0.952941 1"/>
      </material>
    </visual>
    <collision>
      <origin xyz="-2.77556e-17 1.11022e-16 0.11" rpy="-1.5708 2.29729e-15 -1.5708"/>
      <geometry>
        <mesh filename="package://primeu_description/assets/elbow_upper_motor_base_mir.stl"/>
      </geometry>
    </collision>
    <!-- Part elbow_lower_rack_mir -->
    <visual>
      <origin xyz="2.77556e-17 5.55112e-17 0.007" rpy="1.5708 2.3528e-15 -1.5708"/>
      <geometry>
        <mesh filename="package://primeu_description/assets/elbow_lower_rack_mir.stl"/>
      </geometry>
      <material name="elbow_lower_rack_mir_material">
        <color rgba="0.768627 0.886275 0.952941 1"/>
      </material>
    </visual>
    <collision>
      <origin xyz="2.77556e-17 5.55112e-17 0.007" rpy="1.5708 2.3528e-15 -1.5708"/>
      <geometry>
        <mesh filename="package://primeu_description/assets/elbow_lower_rack_mir.stl"/>
      </geometry>
    </collision>
    <!-- Part arm_upper_eblow_case_a_mir -->
    <visual>
      <origin xyz="-0.01453 0.255496 0.163553" rpy="-1.5708 -0.174533 -1.5708"/>
      <geometry>
        <mesh filename="package://primeu_description/assets/arm_upper_eblow_case_a_mir.stl"/>
      </geometry>
      <material name="arm_upper_eblow_case_a_mir_material">
        <color rgba="0.635294 0.686275 0.74902 1"/>
      </material>
    </visual>
    <collision>
      <origin xyz="-0.01453 0.255496 0.163553" rpy="-1.5708 -0.174533 -1.5708"/>
      <geometry>
        <mesh filename="package://primeu_description/assets/arm_upper_eblow_case_a_mir.stl"/>
      </geometry>
    </collision>
    <!-- Part erob70hi_xx_18ex_v0001_5 -->
    <visual>
      <origin xyz="1.19349e-15 0.030725 0.11" rpy="-1.5708 2.29729e-15 -1.5708"/>
      <geometry>
        <mesh filename="package://primeu_description/assets/erob70hi_xx_18ex_v0001.stl"/>
      </geometry>
      <material name="erob70hi_xx_18ex_v0001_5_material">
        <color rgba="0.498039 0.498039 0.498039 1"/>
      </material>
    </visual>
    <collision>
      <origin xyz="1.19349e-15 0.030725 0.11" rpy="-1.5708 2.29729e-15 -1.5708"/>
      <geometry>
        <mesh filename="package://primeu_description/assets/erob70hi_xx_18ex_v0001.stl"/>
      </geometry>
    </collision>
    <!-- Part arm_upper_eblow_case_b_mir -->
    <visual>
      <origin xyz="-0.01453 0.255496 0.163553" rpy="-1.5708 -0.174533 -1.5708"/>
      <geometry>
        <mesh filename="package://primeu_description/assets/arm_upper_eblow_case_b_mir.stl"/>
      </geometry>
      <material name="arm_upper_eblow_case_b_mir_material">
        <color rgba="0.635294 0.686275 0.74902 1"/>
      </material>
    </visual>
    <collision>
      <origin xyz="-0.01453 0.255496 0.163553" rpy="-1.5708 -0.174533 -1.5708"/>
      <geometry>
        <mesh filename="package://primeu_description/assets/arm_upper_eblow_case_b_mir.stl"/>
      </geometry>
    </collision>
    <!-- Part elbow_stopper_base_mir -->
    <visual>
      <origin xyz="2.22045e-15 0.0335 0.11" rpy="-1.5708 9.70115e-15 3.14159"/>
      <geometry>
        <mesh filename="package://primeu_description/assets/elbow_stopper_base_mir.stl"/>
      </geometry>
      <material name="elbow_stopper_base_mir_material">
        <color rgba="0.647059 0.647059 0.647059 1"/>
      </material>
    </visual>
    <collision>
      <origin xyz="2.22045e-15 0.0335 0.11" rpy="-1.5708 9.70115e-15 3.14159"/>
      <geometry>
        <mesh filename="package://primeu_description/assets/elbow_stopper_base_mir.stl"/>
      </geometry>
    </collision>
  </link>
  <!-- Link arm_right_elbow_pitch_link__configuration -->
  <link name="arm_right_elbow_pitch_link__configuration">
    <inertial>
      <origin xyz="-0.0793541 -0.00082566 0.0397519" rpy="0 0 0"/>
      <mass value="1.27258"/>
      <inertia ixx="0.00113564" ixy="2.55175e-05" ixz="-2.82848e-05" iyy="0.00159703" iyz="-3.72338e-07" izz="0.0014711"/>
    </inertial>
    <!-- Part elbow_lower_drive_mir -->
    <visual>
      <origin xyz="-2.77556e-17 3.81639e-17 -0.004" rpy="1.5708 1.5708 0"/>
      <geometry>
        <mesh filename="package://primeu_description/assets/elbow_lower_drive_mir.stl"/>
      </geometry>
      <material name="elbow_lower_drive_mir_material">
        <color rgba="0.768627 0.886275 0.952941 1"/>
      </material>
    </visual>
    <collision>
      <origin xyz="-2.77556e-17 3.81639e-17 -0.004" rpy="1.5708 1.5708 0"/>
      <geometry>
        <mesh filename="package://primeu_description/assets/elbow_lower_drive_mir.stl"/>
      </geometry>
    </collision>
    <!-- Part arm_elbow_lower_case_a_mir -->
    <visual>
      <origin xyz="-0.0536094 0.0145316 0.294997" rpy="-1.5708 1.39626 3.14159"/>
      <geometry>
        <mesh filename="package://primeu_description/assets/arm_elbow_lower_case_a_mir.stl"/>
      </geometry>
      <material name="arm_elbow_lower_case_a_mir_material">
        <color rgba="0.647059 0.647059 0.647059 1"/>
      </material>
    </visual>
    <collision>
      <origin xyz="-0.0536094 0.0145316 0.294997" rpy="-1.5708 1.39626 3.14159"/>
      <geometry>
        <mesh filename="package://primeu_description/assets/arm_elbow_lower_case_a_mir.stl"/>
      </geometry>
    </collision>
    <!-- Part lower_stopper_base_mir -->
    <visual>
      <origin xyz="-0.117 1.57653e-06 0.0395016" rpy="1.5708 -1.5708 0"/>
      <geometry>
        <mesh filename="package://primeu_description/assets/lower_stopper_base_mir.stl"/>
      </geometry>
      <material name="lower_stopper_base_mir_material">
        <color rgba="0.615686 0.811765 0.929412 1"/>
      </material>
    </visual>
    <collision>
      <origin xyz="-0.117 1.57653e-06 0.0395016" rpy="1.5708 -1.5708 0"/>
      <geometry>
        <mesh filename="package://primeu_description/assets/lower_stopper_base_mir.stl"/>
      </geometry>
    </collision>
    <!-- Part elbow_lower_idle_mir -->
    <visual>
      <origin xyz="2.77556e-17 1.57653e-06 0.0830016" rpy="1.5708 1.5708 0"/>
      <geometry>
        <mesh filename="package://primeu_description/assets/elbow_lower_idle_mir.stl"/>
      </geometry>
      <material name="elbow_lower_idle_mir_material">
        <color rgba="0.917647 0.917647 0.917647 1"/>
      </material>
    </visual>
    <collision>
      <origin xyz="2.77556e-17 1.57653e-06 0.0830016" rpy="1.5708 1.5708 0"/>
      <geometry>
        <mesh filename="package://primeu_description/assets/elbow_lower_idle_mir.stl"/>
      </geometry>
    </collision>
    <!-- Part elbow_lower_mir -->
    <visual>
      <origin xyz="-0.117 1.57653e-06 0.0395016" rpy="1.5708 1.5708 0"/>
      <geometry>
        <mesh filename="package://primeu_description/assets/elbow_lower_mir.stl"/>
      </geometry>
      <material name="elbow_lower_mir_material">
        <color rgba="0.972549 0.529412 0.00392157 1"/>
      </material>
    </visual>
    <collision>
      <origin xyz="-0.117 1.57653e-06 0.0395016" rpy="1.5708 1.5708 0"/>
      <geometry>
        <mesh filename="package://primeu_description/assets/elbow_lower_mir.stl"/>
      </geometry>
    </collision>
    <!-- Part erob70hi_xx_18ex_v0001_6 -->
    <visual>
      <origin xyz="-0.114225 1.57653e-06 0.0395016" rpy="-3.14159 7.65582e-15 2.97106e-14"/>
      <geometry>
        <mesh filename="package://primeu_description/assets/erob70hi_xx_18ex_v0001.stl"/>
      </geometry>
      <material name="erob70hi_xx_18ex_v0001_6_material">
        <color rgba="0.498039 0.498039 0.498039 1"/>
      </material>
    </visual>
    <collision>
      <origin xyz="-0.114225 1.57653e-06 0.0395016" rpy="-3.14159 7.65582e-15 2.97106e-14"/>
      <geometry>
        <mesh filename="package://primeu_description/assets/erob70hi_xx_18ex_v0001.stl"/>
      </geometry>
    </collision>
    <!-- Part arm_elbow_lower_case_b_mir -->
    <visual>
      <origin xyz="-0.0536094 0.0145316 0.294997" rpy="-1.5708 1.39626 3.14159"/>
      <geometry>
        <mesh filename="package://primeu_description/assets/arm_elbow_lower_case_b_mir.stl"/>
      </geometry>
      <material name="arm_elbow_lower_case_b_mir_material">
        <color rgba="0.498039 0.498039 0.498039 1"/>
      </material>
    </visual>
    <collision>
      <origin xyz="-0.0536094 0.0145316 0.294997" rpy="-1.5708 1.39626 3.14159"/>
      <geometry>
        <mesh filename="package://primeu_description/assets/arm_elbow_lower_case_b_mir.stl"/>
      </geometry>
    </collision>
  </link>
  <!-- Link arm_right_elbow_roll_link__configuration -->
  <link name="arm_right_elbow_roll_link__configuration">
    <inertial>
      <origin xyz="-5.67209e-05 -4.27687e-05 -0.0388372" rpy="0 0 0"/>
      <mass value="0.497128"/>
      <inertia ixx="0.000602163" ixy="4.29555e-08" ixz="-1.11535e-07" iyy="0.000515444" iyz="1.9846e-05" izz="0.000342693"/>
    </inertial>
    <!-- Part wrist_link_mir -->
    <visual>
      <origin xyz="-0.012 0.03255 -0.099" rpy="-1.5708 -3.34231e-15 3.14159"/>
      <geometry>
        <mesh filename="package://primeu_description/assets/wrist_link_mir.stl"/>
      </geometry>
      <material name="wrist_link_mir_material">
        <color rgba="0.498039 0.498039 0.498039 1"/>
      </material>
    </visual>
    <collision>
      <origin xyz="-0.012 0.03255 -0.099" rpy="-1.5708 -3.34231e-15 3.14159"/>
      <geometry>
        <mesh filename="package://primeu_description/assets/wrist_link_mir.stl"/>
      </geometry>
    </collision>
    <!-- Part wrist_rack_bottom_2 -->
    <visual>
      <origin xyz="2.48065e-15 -0.023 -0.039" rpy="1.5708 -1.03117e-14 3.14159"/>
      <geometry>
        <mesh filename="package://primeu_description/assets/wrist_rack_bottom.stl"/>
      </geometry>
      <material name="wrist_rack_bottom_2_material">
        <color rgba="0.615686 0.811765 0.929412 1"/>
      </material>
    </visual>
    <collision>
      <origin xyz="2.48065e-15 -0.023 -0.039" rpy="1.5708 -1.03117e-14 3.14159"/>
      <geometry>
        <mesh filename="package://primeu_description/assets/wrist_rack_bottom.stl"/>
      </geometry>
    </collision>
    <!-- Part wrist_rack_front_mir -->
    <visual>
      <origin xyz="5.62744e-15 0.023 -0.039" rpy="1.5708 1.58665e-14 -1.65507e-13"/>
      <geometry>
        <mesh filename="package://primeu_description/assets/wrist_rack_front_mir.stl"/>
      </geometry>
      <material name="wrist_rack_front_mir_material">
        <color rgba="0.498039 0.498039 0.498039 1"/>
      </material>
    </visual>
    <collision>
      <origin xyz="5.62744e-15 0.023 -0.039" rpy="1.5708 1.58665e-14 -1.65507e-13"/>
      <geometry>
        <mesh filename="package://primeu_description/assets/wrist_rack_front_mir.stl"/>
      </geometry>
    </collision>
    <!-- Part elbow_lower_rack_mir_2 -->
    <visual>
      <origin xyz="3.46945e-17 1.11022e-16 -0.007" rpy="-1.5708 -3.08801e-15 3.14159"/>
      <geometry>
        <mesh filename="package://primeu_description/assets/elbow_lower_rack_mir.stl"/>
      </geometry>
      <material name="elbow_lower_rack_mir_2_material">
        <color rgba="0.768627 0.886275 0.952941 1"/>
      </material>
    </visual>
    <collision>
      <origin xyz="3.46945e-17 1.11022e-16 -0.007" rpy="-1.5708 -3.08801e-15 3.14159"/>
      <geometry>
        <mesh filename="package://primeu_description/assets/elbow_lower_rack_mir.stl"/>
      </geometry>
    </collision>
    <!-- Part wrist_yaw_crank_mir -->
    <visual>
      <origin xyz="3.46251e-15 0.02955 -0.039" rpy="-1.5708 -3.34231e-15 3.14159"/>
      <geometry>
        <mesh filename="package://primeu_description/assets/wrist_yaw_crank_mir.stl"/>
      </geometry>
      <material name="wrist_yaw_crank_mir_material">
        <color rgba="0.231373 0.380392 0.705882 1"/>
      </material>
    </visual>
    <collision>
      <origin xyz="3.46251e-15 0.02955 -0.039" rpy="-1.5708 -3.34231e-15 3.14159"/>
      <geometry>
        <mesh filename="package://primeu_description/assets/wrist_yaw_crank_mir.stl"/>
      </geometry>
    </collision>
    <!-- Part arm_lower_wrist_case_a_mir -->
    <visual>
      <origin xyz="-0.01453 -0.255496 0.0703906" rpy="1.5708 0.174533 1.5708"/>
      <geometry>
        <mesh filename="package://primeu_description/assets/arm_lower_wrist_case_a_mir.stl"/>
      </geometry>
      <material name="arm_lower_wrist_case_a_mir_material">
        <color rgba="0.615686 0.811765 0.929412 1"/>
      </material>
    </visual>
    <collision>
      <origin xyz="-0.01453 -0.255496 0.0703906" rpy="1.5708 0.174533 1.5708"/>
      <geometry>
        <mesh filename="package://primeu_description/assets/arm_lower_wrist_case_a_mir.stl"/>
      </geometry>
    </collision>
    <!-- Part ta_40_4 -->
    <visual>
      <origin xyz="1.21084e-15 -0.0305 -0.039" rpy="1.5708 -6.12331e-15 3.14159"/>
      <geometry>
        <mesh filename="package://primeu_description/assets/ta_40__2.stl"/>
      </geometry>
      <material name="ta_40_4_material">
        <color rgba="0.615686 0.811765 0.929412 1"/>
      </material>
    </visual>
    <collision>
      <origin xyz="1.21084e-15 -0.0305 -0.039" rpy="1.5708 -6.12331e-15 3.14159"/>
      <geometry>
        <mesh filename="package://primeu_description/assets/ta_40__2.stl"/>
      </geometry>
    </collision>
    <!-- Part bearing_30_37_4_3 -->
    <visual>
      <origin xyz="5.36723e-15 0.024 -0.099" rpy="-1.5708 -3.59836e-15 3.14159"/>
      <geometry>
        <mesh filename="package://primeu_description/assets/bearing_30_37_4.stl"/>
      </geometry>
      <material name="bearing_30_37_4_3_material">
        <color rgba="0.768627 0.886275 0.952941 1"/>
      </material>
    </visual>
    <collision>
      <origin xyz="5.36723e-15 0.024 -0.099" rpy="-1.5708 -3.59836e-15 3.14159"/>
      <geometry>
        <mesh filename="package://primeu_description/assets/bearing_30_37_4.stl"/>
      </geometry>
    </collision>
    <!-- Part arm_lower_wrist_case_b_mir -->
    <visual>
      <origin xyz="-0.01453 -0.255496 0.0703906" rpy="1.5708 0.174533 1.5708"/>
      <geometry>
        <mesh filename="package://primeu_description/assets/arm_lower_wrist_case_b_mir.stl"/>
      </geometry>
      <material name="arm_lower_wrist_case_b_mir_material">
        <color rgba="0.615686 0.811765 0.929412 1"/>
      </material>
    </visual>
    <collision>
      <origin xyz="-0.01453 -0.255496 0.0703906" rpy="1.5708 0.174533 1.5708"/>
      <geometry>
        <mesh filename="package://primeu_description/assets/arm_lower_wrist_case_b_mir.stl"/>
      </geometry>
    </collision>
    <!-- Part bearing_30_37_4_4 -->
    <visual>
      <origin xyz="2.39045e-15 -0.024 -0.099" rpy="-1.5708 -3.25454e-15 3.14159"/>
      <geometry>
        <mesh filename="package://primeu_description/assets/bearing_30_37_4.stl"/>
      </geometry>
      <material name="bearing_30_37_4_4_material">
        <color rgba="0.768627 0.886275 0.952941 1"/>
      </material>
    </visual>
    <collision>
      <origin xyz="2.39045e-15 -0.024 -0.099" rpy="-1.5708 -3.25454e-15 3.14159"/>
      <geometry>
        <mesh filename="package://primeu_description/assets/bearing_30_37_4.stl"/>
      </geometry>
    </collision>
    <!-- Part wrist_link_mir_2 -->
    <visual>
      <origin xyz="0.012 0.03255 -0.099" rpy="-1.5708 -3.34231e-15 3.14159"/>
      <geometry>
        <mesh filename="package://primeu_description/assets/wrist_link_mir.stl"/>
      </geometry>
      <material name="wrist_link_mir_2_material">
        <color rgba="0.498039 0.498039 0.498039 1"/>
      </material>
    </visual>
    <collision>
      <origin xyz="0.012 0.03255 -0.099" rpy="-1.5708 -3.34231e-15 3.14159"/>
      <geometry>
        <mesh filename="package://primeu_description/assets/wrist_link_mir.stl"/>
      </geometry>
    </collision>
    <!-- Part wrist_lower_link_mir -->
    <visual>
      <origin xyz="2.61249e-15 8.32667e-16 -0.009" rpy="1.5708 -6.70168e-15 3.14159"/>
      <geometry>
        <mesh filename="package://primeu_description/assets/wrist_lower_link_mir.stl"/>
      </geometry>
      <material name="wrist_lower_link_mir_material">
        <color rgba="0.917647 0.917647 0.917647 1"/>
      </material>
    </visual>
    <collision>
      <origin xyz="2.61249e-15 8.32667e-16 -0.009" rpy="1.5708 -6.70168e-15 3.14159"/>
      <geometry>
        <mesh filename="package://primeu_description/assets/wrist_lower_link_mir.stl"/>
      </geometry>
    </collision>
  </link>
  <!-- Link arm_right_elbow_yaw_link -->
  <link name="arm_right_elbow_yaw_link">
    <inertial>
      <origin xyz="-0.00106391 1.95317e-10 -0.0220599" rpy="0 0 0"/>
      <mass value="0.304398"/>
      <inertia ixx="8.08744e-05" ixy="-3.53175e-13" ixz="5.34681e-07" iyy="0.000118571" iyz="-9.46581e-11" izz="0.000107519"/>
    </inertial>
    <!-- Part gearing_bottom_stopper_mir -->
    <visual>
      <origin xyz="1.30798e-15 7.71605e-15 -0.049" rpy="-3.14159 -1.13345e-15 -8.67357e-16"/>
      <geometry>
        <mesh filename="package://primeu_description/assets/gearing_bottom_stopper_mir.stl"/>
      </geometry>
      <material name="gearing_bottom_stopper_mir_material">
        <color rgba="0.768627 0.886275 0.952941 1"/>
      </material>
    </visual>
    <collision>
      <origin xyz="1.30798e-15 7.71605e-15 -0.049" rpy="-3.14159 -1.13345e-15 -8.67357e-16"/>
      <geometry>
        <mesh filename="package://primeu_description/assets/gearing_bottom_stopper_mir.stl"/>
      </geometry>
    </collision>
    <!-- Part wrist_pitch_motor_base_mir -->
    <visual>
      <origin xyz="3.46945e-17 0 -0.022" rpy="3.14159 1.5402e-17 -2.39374e-17"/>
      <geometry>
        <mesh filename="package://primeu_description/assets/wrist_pitch_motor_base_mir.stl"/>
      </geometry>
      <material name="wrist_pitch_motor_base_mir_material">
        <color rgba="0.972549 0.529412 0.00392157 1"/>
      </material>
    </visual>
    <collision>
      <origin xyz="3.46945e-17 0 -0.022" rpy="3.14159 1.5402e-17 -2.39374e-17"/>
      <geometry>
        <mesh filename="package://primeu_description/assets/wrist_pitch_motor_base_mir.stl"/>
      </geometry>
    </collision>
    <!-- Part ta_40_5 -->
    <visual>
      <origin xyz="0.024 4.996e-15 -0.022" rpy="3.14159 1.5708 0"/>
      <geometry>
        <mesh filename="package://primeu_description/assets/ta_40__2.stl"/>
      </geometry>
      <material name="ta_40_5_material">
        <color rgba="0.615686 0.811765 0.929412 1"/>
      </material>
    </visual>
    <collision>
      <origin xyz="0.024 4.996e-15 -0.022" rpy="3.14159 1.5708 0"/>
      <geometry>
        <mesh filename="package://primeu_description/assets/ta_40__2.stl"/>
      </geometry>
    </collision>
    <!-- Part wrist_pitch_gearing_base_mir -->
    <visual>
      <origin xyz="0.0243 3.27516e-15 -0.022" rpy="-1.5708 5.81512e-14 2.81818e-14"/>
      <geometry>
        <mesh filename="package://primeu_description/assets/wrist_pitch_gearing_base_mir.stl"/>
      </geometry>
      <material name="wrist_pitch_gearing_base_mir_material">
        <color rgba="0.917647 0.917647 0.917647 1"/>
      </material>
    </visual>
    <collision>
      <origin xyz="0.0243 3.27516e-15 -0.022" rpy="-1.5708 5.81512e-14 2.81818e-14"/>
      <geometry>
        <mesh filename="package://primeu_description/assets/wrist_pitch_gearing_base_mir.stl"/>
      </geometry>
    </collision>
    <!-- Part gearing_front_stopper_mir -->
    <visual>
      <origin xyz="4.85723e-16 -7.16094e-15 0.005" rpy="-3.14159 1.72364e-13 -1.5708"/>
      <geometry>
        <mesh filename="package://primeu_description/assets/gearing_front_stopper_mir.stl"/>
      </geometry>
      <material name="gearing_front_stopper_mir_material">
        <color rgba="0.980392 0.713725 0.00392157 1"/>
      </material>
    </visual>
    <collision>
      <origin xyz="4.85723e-16 -7.16094e-15 0.005" rpy="-3.14159 1.72364e-13 -1.5708"/>
      <geometry>
        <mesh filename="package://primeu_description/assets/gearing_front_stopper_mir.stl"/>
      </geometry>
    </collision>
  </link>
  <!-- Link arm_right_wrist_pitch_link -->
  <link name="arm_right_wrist_pitch_link">
    <inertial>
      <origin xyz="0 0 0" rpy="0 0 0"/>
      <mass value="1e-09"/>
      <inertia ixx="1e-09" ixy="0" ixz="0" iyy="1e-09" iyz="0" izz="1e-09"/>
    </inertial>
    <!-- Part wrist_connecting_2 -->
    <visual>
      <origin xyz="-2.16493e-15 0.035 0.03005" rpy="-3.14159 -1.60312e-14 1.92107e-14"/>
      <geometry>
        <mesh filename="package://primeu_description/assets/wrist_connecting.stl"/>
      </geometry>
      <material name="wrist_connecting_2_material">
        <color rgba="0.615686 0.811765 0.929412 1"/>
      </material>
    </visual>
    <collision>
      <origin xyz="-2.16493e-15 0.035 0.03005" rpy="-3.14159 -1.60312e-14 1.92107e-14"/>
      <geometry>
        <mesh filename="package://primeu_description/assets/wrist_connecting.stl"/>
      </geometry>
    </collision>
    <!-- Part wrist_drive_2 -->
    <visual>
      <origin xyz="-1.11022e-16 5.55112e-17 -0.00445" rpy="-3.14159 -1.59927e-14 1.92832e-14"/>
      <geometry>
        <mesh filename="package://primeu_description/assets/wrist_drive.stl"/>
      </geometry>
      <material name="wrist_drive_2_material">
        <color rgba="0.647059 0.647059 0.647059 1"/>
      </material>
    </visual>
    <collision>
      <origin xyz="-1.11022e-16 5.55112e-17 -0.00445" rpy="-3.14159 -1.59927e-14 1.92832e-14"/>
      <geometry>
        <mesh filename="package://primeu_description/assets/wrist_drive.stl"/>
      </geometry>
    </collision>
    <!-- Part wrist_idle_2 -->
    <visual>
      <origin xyz="-2.38698e-15 2.22045e-16 0.06455" rpy="3.14159 1.02699e-14 1.09346e-13"/>
      <geometry>
        <mesh filename="package://primeu_description/assets/wrist_idle.stl"/>
      </geometry>
      <material name="wrist_idle_2_material">
        <color rgba="0.498039 0.498039 0.498039 1"/>
      </material>
    </visual>
    <collision>
      <origin xyz="-2.38698e-15 2.22045e-16 0.06455" rpy="3.14159 1.02699e-14 1.09346e-13"/>
      <geometry>
        <mesh filename="package://primeu_description/assets/wrist_idle.stl"/>
      </geometry>
    </collision>
  </link>
  <!-- Joint from arm_right_elbow_yaw_link to arm_right_wrist_pitch_link -->
  <joint name="arm_right_wrist_pitch_joint" type="revolute">
    <origin xyz="-0.03005 1.60982e-15 -0.022" rpy="-6.25643e-14 1.5708 0"/>
    <parent link="arm_right_elbow_yaw_link"/>
    <child link="arm_right_wrist_pitch_link"/>
    <axis xyz="0 0 1"/>
    <limit effort="5.0" velocity="6.0" lower="-1.5708" upper="1.5708"/>
    <joint_properties friction="0.5"/>
  </joint>
  <!-- Joint from arm_right_elbow_roll_link__configuration to arm_right_elbow_yaw_link -->
  <joint name="arm_right_wrist_roll_joint" type="revolute">
    <origin xyz="5.44703e-15 0.022 -0.099" rpy="-1.5708 3.17271e-15 6.35505e-15"/>
    <parent link="arm_right_elbow_roll_link__configuration"/>
    <child link="arm_right_elbow_yaw_link"/>
    <axis xyz="0 0 1"/>
    <limit effort="5.0" velocity="6.0" lower="-0.785398" upper="0.785398"/>
    <joint_properties friction="0.5"/>
  </joint>
  <!-- Joint from arm_right_elbow_pitch_link__configuration to arm_right_elbow_roll_link__configuration -->
  <joint name="arm_right_wrist_yaw_joint" type="revolute">
    <origin xyz="-0.124 1.57653e-06 0.0395016" rpy="-1.5708 1.06703e-14 -1.5708"/>
    <parent link="arm_right_elbow_pitch_link__configuration"/>
    <child link="arm_right_elbow_roll_link__configuration"/>
    <axis xyz="0 0 -1"/>
    <limit effort="5.0" velocity="6.0" lower="-1.5708" upper="1.5708"/>
    <joint_properties friction="0.5"/>
  </joint>
  <!-- Joint from arm_right_shoulder_yaw_link__configuration to arm_right_elbow_pitch_link__configuration -->
  <joint name="arm_right_elbow_pitch_joint" type="revolute">
    <origin xyz="-1.47105e-15 -0.0395 0.11" rpy="-1.5708 0.392699 -3.9302e-14"/>
    <parent link="arm_right_shoulder_yaw_link__configuration"/>
    <child link="arm_right_elbow_pitch_link__configuration"/>
    <axis xyz="0 0 1"/>
    <limit effort="5.0" velocity="6.0" lower="-1.1781" upper="1.1781"/>
    <joint_properties friction="0.5"/>
  </joint>
  <!-- Joint from arm_right_shoulder_roll_link__configuration_default to arm_right_shoulder_yaw_link__configuration -->
  <joint name="arm_right_shoulder_yaw_joint" type="revolute">
    <origin xyz="-0.16 5.55112e-17 0.041" rpy="-3.41345e-14 -1.5708 0"/>
    <parent link="arm_right_shoulder_roll_link__configuration_default"/>
    <child link="arm_right_shoulder_yaw_link__configuration"/>
    <axis xyz="0 0 1"/>
    <limit effort="5.0" velocity="6.0" lower="-1.5708" upper="1.5708"/>
    <joint_properties friction="0.5"/>
  </joint>
  <!-- Joint from arm_right_shoulder_pitch_link__configuration to arm_right_shoulder_roll_link__configuration_default -->
  <joint name="arm_right_shoulder_roll_joint" type="revolute">
    <origin xyz="0.041 -1.38778e-16 0.06" rpy="-1.5708 0.261799 1.5708"/>
    <parent link="arm_right_shoulder_pitch_link__configuration"/>
    <child link="arm_right_shoulder_roll_link__configuration_default"/>
    <axis xyz="0 0 1"/>
    <limit effort="5.0" velocity="6.0" lower="-1.0472" upper="1.0472"/>
    <joint_properties friction="0.5"/>
  </joint>
  <!-- Joint from chest_link__configuration_default to arm_right_shoulder_pitch_link__configuration -->
  <joint name="arm_right_shoulder_pitch_joint" type="revolute">
    <origin xyz="0.01443 0.247814 -0.114316" rpy="3.01755 -0.123098 2.36385"/>
    <parent link="chest_link__configuration_default"/>
    <child link="arm_right_shoulder_pitch_link__configuration"/>
    <axis xyz="0 0 1"/>
    <limit effort="5.0" velocity="6.0" lower="-2.35619" upper="2.35619"/>
    <joint_properties friction="0.5"/>
  </joint>
  <!-- Joint from waist_roll_link to chest_link__configuration_default -->
  <joint name="waist_pitch_joint" type="revolute">
    <origin xyz="-0.023 -4.3715e-15 -0.0177" rpy="-3.14159 -1.5708 0"/>
    <parent link="waist_roll_link"/>
    <child link="chest_link__configuration_default"/>
    <axis xyz="0 0 1"/>
    <limit effort="5.0" velocity="6.0" lower="-0.785398" upper="0.785398"/>
    <joint_properties friction="0.5"/>
  </joint>
  <!-- Joint from waist_yaw_link to waist_roll_link -->
  <joint name="waist_roll_joint" type="revolute">
    <origin xyz="-1.31023e-14 -0.018 -0.035" rpy="1.5708 4.08562e-14 4.76841e-14"/>
    <parent link="waist_yaw_link"/>
    <child link="waist_roll_link"/>
    <axis xyz="0 0 1"/>
    <limit effort="5.0" velocity="6.0" lower="-0.174533" upper="0.174533"/>
    <joint_properties friction="0.5"/>
  </joint>
  <!-- Joint from body_base to waist_yaw_link -->
  <joint name="waist_yaw_joint" type="revolute">
    <origin xyz="-1.05756e-16 2.26373e-17 0.0508" rpy="-3.14159 8.88178e-16 1.5708"/>
    <parent link="body_base"/>
    <child link="waist_yaw_link"/>
    <axis xyz="0 0 1"/>
    <limit effort="5.0" velocity="6.0" lower="-1.5708" upper="1.5708"/>
    <joint_properties friction="0.5"/>
  </joint>
  </xacro:macro>
</robot>
